Workbook
Name ____________________________FG1: {#N/A,#N/A,FALSE,"단축1";#N/A,#N/A,FALSE,"단축2";#N/A,#N/A,FALSE,"단축3";#N/A,#N/A,FALSE,"장축";#N/A,#N/A,FALSE,"4WD"}
Name ____________________________FG1: {#N/A,#N/A,FALSE,"단축1";#N/A,#N/A,FALSE,"단축2";#N/A,#N/A,FALSE,"단축3";#N/A,#N/A,FALSE,"장축";#N/A,#N/A,FALSE,"4WD"}
Name ____________________________FG1: {#N/A,#N/A,FALSE,"단축1";#N/A,#N/A,FALSE,"단축2";#N/A,#N/A,FALSE,"단축3";#N/A,#N/A,FALSE,"장축";#N/A,#N/A,FALSE,"4WD"}
Name ____________________________FG1: {#N/A,#N/A,FALSE,"단축1";#N/A,#N/A,FALSE,"단축2";#N/A,#N/A,FALSE,"단축3";#N/A,#N/A,FALSE,"장축";#N/A,#N/A,FALSE,"4WD"}
Name ____________________________T2: {#N/A,#N/A,FALSE,"단축1";#N/A,#N/A,FALSE,"단축2";#N/A,#N/A,FALSE,"단축3";#N/A,#N/A,FALSE,"장축";#N/A,#N/A,FALSE,"4WD"}
Name ____________________________T2: {#N/A,#N/A,FALSE,"단축1";#N/A,#N/A,FALSE,"단축2";#N/A,#N/A,FALSE,"단축3";#N/A,#N/A,FALSE,"장축";#N/A,#N/A,FALSE,"4WD"}
Name ____________________________T2: {#N/A,#N/A,FALSE,"단축1";#N/A,#N/A,FALSE,"단축2";#N/A,#N/A,FALSE,"단축3";#N/A,#N/A,FALSE,"장축";#N/A,#N/A,FALSE,"4WD"}
Name ____________________________T2: {#N/A,#N/A,FALSE,"단축1";#N/A,#N/A,FALSE,"단축2";#N/A,#N/A,FALSE,"단축3";#N/A,#N/A,FALSE,"장축";#N/A,#N/A,FALSE,"4WD"}
Name ____________________________T3: {#N/A,#N/A,FALSE,"단축1";#N/A,#N/A,FALSE,"단축2";#N/A,#N/A,FALSE,"단축3";#N/A,#N/A,FALSE,"장축";#N/A,#N/A,FALSE,"4WD"}
Name ____________________________T3: {#N/A,#N/A,FALSE,"단축1";#N/A,#N/A,FALSE,"단축2";#N/A,#N/A,FALSE,"단축3";#N/A,#N/A,FALSE,"장축";#N/A,#N/A,FALSE,"4WD"}
Name ____________________________T3: {#N/A,#N/A,FALSE,"단축1";#N/A,#N/A,FALSE,"단축2";#N/A,#N/A,FALSE,"단축3";#N/A,#N/A,FALSE,"장축";#N/A,#N/A,FALSE,"4WD"}
Name ____________________________T3: {#N/A,#N/A,FALSE,"단축1";#N/A,#N/A,FALSE,"단축2";#N/A,#N/A,FALSE,"단축3";#N/A,#N/A,FALSE,"장축";#N/A,#N/A,FALSE,"4WD"}
Name ____________________________T5: {#N/A,#N/A,FALSE,"단축1";#N/A,#N/A,FALSE,"단축2";#N/A,#N/A,FALSE,"단축3";#N/A,#N/A,FALSE,"장축";#N/A,#N/A,FALSE,"4WD"}
Name ____________________________T5: {#N/A,#N/A,FALSE,"단축1";#N/A,#N/A,FALSE,"단축2";#N/A,#N/A,FALSE,"단축3";#N/A,#N/A,FALSE,"장축";#N/A,#N/A,FALSE,"4WD"}
Name ____________________________T5: {#N/A,#N/A,FALSE,"단축1";#N/A,#N/A,FALSE,"단축2";#N/A,#N/A,FALSE,"단축3";#N/A,#N/A,FALSE,"장축";#N/A,#N/A,FALSE,"4WD"}
Name ____________________________T5: {#N/A,#N/A,FALSE,"단축1";#N/A,#N/A,FALSE,"단축2";#N/A,#N/A,FALSE,"단축3";#N/A,#N/A,FALSE,"장축";#N/A,#N/A,FALSE,"4WD"}
Name ___________________________FG1: {#N/A,#N/A,FALSE,"단축1";#N/A,#N/A,FALSE,"단축2";#N/A,#N/A,FALSE,"단축3";#N/A,#N/A,FALSE,"장축";#N/A,#N/A,FALSE,"4WD"}
Name ___________________________FG1: {#N/A,#N/A,FALSE,"단축1";#N/A,#N/A,FALSE,"단축2";#N/A,#N/A,FALSE,"단축3";#N/A,#N/A,FALSE,"장축";#N/A,#N/A,FALSE,"4WD"}
Name ___________________________FG1: {#N/A,#N/A,FALSE,"단축1";#N/A,#N/A,FALSE,"단축2";#N/A,#N/A,FALSE,"단축3";#N/A,#N/A,FALSE,"장축";#N/A,#N/A,FALSE,"4WD"}
Name ___________________________FG1: {#N/A,#N/A,FALSE,"단축1";#N/A,#N/A,FALSE,"단축2";#N/A,#N/A,FALSE,"단축3";#N/A,#N/A,FALSE,"장축";#N/A,#N/A,FALSE,"4WD"}
Name ___________________________T2: {#N/A,#N/A,FALSE,"단축1";#N/A,#N/A,FALSE,"단축2";#N/A,#N/A,FALSE,"단축3";#N/A,#N/A,FALSE,"장축";#N/A,#N/A,FALSE,"4WD"}
Name ___________________________T2: {#N/A,#N/A,FALSE,"단축1";#N/A,#N/A,FALSE,"단축2";#N/A,#N/A,FALSE,"단축3";#N/A,#N/A,FALSE,"장축";#N/A,#N/A,FALSE,"4WD"}
Name ___________________________T2: {#N/A,#N/A,FALSE,"단축1";#N/A,#N/A,FALSE,"단축2";#N/A,#N/A,FALSE,"단축3";#N/A,#N/A,FALSE,"장축";#N/A,#N/A,FALSE,"4WD"}
Name ___________________________T2: {#N/A,#N/A,FALSE,"단축1";#N/A,#N/A,FALSE,"단축2";#N/A,#N/A,FALSE,"단축3";#N/A,#N/A,FALSE,"장축";#N/A,#N/A,FALSE,"4WD"}
Name ___________________________T3: {#N/A,#N/A,FALSE,"단축1";#N/A,#N/A,FALSE,"단축2";#N/A,#N/A,FALSE,"단축3";#N/A,#N/A,FALSE,"장축";#N/A,#N/A,FALSE,"4WD"}
Name ___________________________T3: {#N/A,#N/A,FALSE,"단축1";#N/A,#N/A,FALSE,"단축2";#N/A,#N/A,FALSE,"단축3";#N/A,#N/A,FALSE,"장축";#N/A,#N/A,FALSE,"4WD"}
Name ___________________________T3: {#N/A,#N/A,FALSE,"단축1";#N/A,#N/A,FALSE,"단축2";#N/A,#N/A,FALSE,"단축3";#N/A,#N/A,FALSE,"장축";#N/A,#N/A,FALSE,"4WD"}
Name ___________________________T3: {#N/A,#N/A,FALSE,"단축1";#N/A,#N/A,FALSE,"단축2";#N/A,#N/A,FALSE,"단축3";#N/A,#N/A,FALSE,"장축";#N/A,#N/A,FALSE,"4WD"}
Name ___________________________T5: {#N/A,#N/A,FALSE,"단축1";#N/A,#N/A,FALSE,"단축2";#N/A,#N/A,FALSE,"단축3";#N/A,#N/A,FALSE,"장축";#N/A,#N/A,FALSE,"4WD"}
Name ___________________________T5: {#N/A,#N/A,FALSE,"단축1";#N/A,#N/A,FALSE,"단축2";#N/A,#N/A,FALSE,"단축3";#N/A,#N/A,FALSE,"장축";#N/A,#N/A,FALSE,"4WD"}
Name ___________________________T5: {#N/A,#N/A,FALSE,"단축1";#N/A,#N/A,FALSE,"단축2";#N/A,#N/A,FALSE,"단축3";#N/A,#N/A,FALSE,"장축";#N/A,#N/A,FALSE,"4WD"}
Name ___________________________T5: {#N/A,#N/A,FALSE,"단축1";#N/A,#N/A,FALSE,"단축2";#N/A,#N/A,FALSE,"단축3";#N/A,#N/A,FALSE,"장축";#N/A,#N/A,FALSE,"4WD"}
Name _________________________FG1: {#N/A,#N/A,FALSE,"단축1";#N/A,#N/A,FALSE,"단축2";#N/A,#N/A,FALSE,"단축3";#N/A,#N/A,FALSE,"장축";#N/A,#N/A,FALSE,"4WD"}
Name _________________________FG1: {#N/A,#N/A,FALSE,"단축1";#N/A,#N/A,FALSE,"단축2";#N/A,#N/A,FALSE,"단축3";#N/A,#N/A,FALSE,"장축";#N/A,#N/A,FALSE,"4WD"}
Name _________________________FG1: {#N/A,#N/A,FALSE,"단축1";#N/A,#N/A,FALSE,"단축2";#N/A,#N/A,FALSE,"단축3";#N/A,#N/A,FALSE,"장축";#N/A,#N/A,FALSE,"4WD"}
Name _________________________FG1: {#N/A,#N/A,FALSE,"단축1";#N/A,#N/A,FALSE,"단축2";#N/A,#N/A,FALSE,"단축3";#N/A,#N/A,FALSE,"장축";#N/A,#N/A,FALSE,"4WD"}
Name _________________________H1620: {#N/A,#N/A,FALSE,"단축1";#N/A,#N/A,FALSE,"단축2";#N/A,#N/A,FALSE,"단축3";#N/A,#N/A,FALSE,"장축";#N/A,#N/A,FALSE,"4WD"}
Name _________________________H1620: {#N/A,#N/A,FALSE,"단축1";#N/A,#N/A,FALSE,"단축2";#N/A,#N/A,FALSE,"단축3";#N/A,#N/A,FALSE,"장축";#N/A,#N/A,FALSE,"4WD"}
Name _________________________H1620: {#N/A,#N/A,FALSE,"단축1";#N/A,#N/A,FALSE,"단축2";#N/A,#N/A,FALSE,"단축3";#N/A,#N/A,FALSE,"장축";#N/A,#N/A,FALSE,"4WD"}
Name _________________________H1620: {#N/A,#N/A,FALSE,"단축1";#N/A,#N/A,FALSE,"단축2";#N/A,#N/A,FALSE,"단축3";#N/A,#N/A,FALSE,"장축";#N/A,#N/A,FALSE,"4WD"}
Name _________________________H20: {#N/A,#N/A,FALSE,"단축1";#N/A,#N/A,FALSE,"단축2";#N/A,#N/A,FALSE,"단축3";#N/A,#N/A,FALSE,"장축";#N/A,#N/A,FALSE,"4WD"}
Name _________________________H20: {#N/A,#N/A,FALSE,"단축1";#N/A,#N/A,FALSE,"단축2";#N/A,#N/A,FALSE,"단축3";#N/A,#N/A,FALSE,"장축";#N/A,#N/A,FALSE,"4WD"}
Name _________________________H20: {#N/A,#N/A,FALSE,"단축1";#N/A,#N/A,FALSE,"단축2";#N/A,#N/A,FALSE,"단축3";#N/A,#N/A,FALSE,"장축";#N/A,#N/A,FALSE,"4WD"}
Name _________________________H20: {#N/A,#N/A,FALSE,"단축1";#N/A,#N/A,FALSE,"단축2";#N/A,#N/A,FALSE,"단축3";#N/A,#N/A,FALSE,"장축";#N/A,#N/A,FALSE,"4WD"}
Name _________________________P2: {#N/A,#N/A,FALSE,"단축1";#N/A,#N/A,FALSE,"단축2";#N/A,#N/A,FALSE,"단축3";#N/A,#N/A,FALSE,"장축";#N/A,#N/A,FALSE,"4WD"}
Name _________________________P2: {#N/A,#N/A,FALSE,"단축1";#N/A,#N/A,FALSE,"단축2";#N/A,#N/A,FALSE,"단축3";#N/A,#N/A,FALSE,"장축";#N/A,#N/A,FALSE,"4WD"}
Name _________________________P2: {#N/A,#N/A,FALSE,"단축1";#N/A,#N/A,FALSE,"단축2";#N/A,#N/A,FALSE,"단축3";#N/A,#N/A,FALSE,"장축";#N/A,#N/A,FALSE,"4WD"}
Name _________________________P2: {#N/A,#N/A,FALSE,"단축1";#N/A,#N/A,FALSE,"단축2";#N/A,#N/A,FALSE,"단축3";#N/A,#N/A,FALSE,"장축";#N/A,#N/A,FALSE,"4WD"}
Name _________________________T2: {#N/A,#N/A,FALSE,"단축1";#N/A,#N/A,FALSE,"단축2";#N/A,#N/A,FALSE,"단축3";#N/A,#N/A,FALSE,"장축";#N/A,#N/A,FALSE,"4WD"}
Name _________________________T2: {#N/A,#N/A,FALSE,"단축1";#N/A,#N/A,FALSE,"단축2";#N/A,#N/A,FALSE,"단축3";#N/A,#N/A,FALSE,"장축";#N/A,#N/A,FALSE,"4WD"}
Name _________________________T2: {#N/A,#N/A,FALSE,"단축1";#N/A,#N/A,FALSE,"단축2";#N/A,#N/A,FALSE,"단축3";#N/A,#N/A,FALSE,"장축";#N/A,#N/A,FALSE,"4WD"}
Name _________________________T2: {#N/A,#N/A,FALSE,"단축1";#N/A,#N/A,FALSE,"단축2";#N/A,#N/A,FALSE,"단축3";#N/A,#N/A,FALSE,"장축";#N/A,#N/A,FALSE,"4WD"}
Name _________________________T3: {#N/A,#N/A,FALSE,"단축1";#N/A,#N/A,FALSE,"단축2";#N/A,#N/A,FALSE,"단축3";#N/A,#N/A,FALSE,"장축";#N/A,#N/A,FALSE,"4WD"}
Name _________________________T3: {#N/A,#N/A,FALSE,"단축1";#N/A,#N/A,FALSE,"단축2";#N/A,#N/A,FALSE,"단축3";#N/A,#N/A,FALSE,"장축";#N/A,#N/A,FALSE,"4WD"}
Name _________________________T3: {#N/A,#N/A,FALSE,"단축1";#N/A,#N/A,FALSE,"단축2";#N/A,#N/A,FALSE,"단축3";#N/A,#N/A,FALSE,"장축";#N/A,#N/A,FALSE,"4WD"}
Name _________________________T3: {#N/A,#N/A,FALSE,"단축1";#N/A,#N/A,FALSE,"단축2";#N/A,#N/A,FALSE,"단축3";#N/A,#N/A,FALSE,"장축";#N/A,#N/A,FALSE,"4WD"}
Name _________________________T5: {#N/A,#N/A,FALSE,"단축1";#N/A,#N/A,FALSE,"단축2";#N/A,#N/A,FALSE,"단축3";#N/A,#N/A,FALSE,"장축";#N/A,#N/A,FALSE,"4WD"}
Name _________________________T5: {#N/A,#N/A,FALSE,"단축1";#N/A,#N/A,FALSE,"단축2";#N/A,#N/A,FALSE,"단축3";#N/A,#N/A,FALSE,"장축";#N/A,#N/A,FALSE,"4WD"}
Name _________________________T5: {#N/A,#N/A,FALSE,"단축1";#N/A,#N/A,FALSE,"단축2";#N/A,#N/A,FALSE,"단축3";#N/A,#N/A,FALSE,"장축";#N/A,#N/A,FALSE,"4WD"}
Name _________________________T5: {#N/A,#N/A,FALSE,"단축1";#N/A,#N/A,FALSE,"단축2";#N/A,#N/A,FALSE,"단축3";#N/A,#N/A,FALSE,"장축";#N/A,#N/A,FALSE,"4WD"}

Sheet  55648-98655
A1: 비 교 원 가 계 산 서
A3: 품 번 : 55648-98655 | AH3: 차 종 : qq5
A4: 품 명 : GANH ASY RASPAD D/SIDE | AH4: 업 체 : 지-텍텍텍(DDDD)
A5: EO NO : ABC564 | AH5: 작성일자 : 22.1.21
A7: 구 분 | E7: T 초도가 제출 (A) | N7: 입찰가 (A) | W7: 초도가 (B) | AF7: 차이 (C-A) | AG7: 차이 (B-A) | AH7: 비 고
E9: 재 질 | G9: LOSS율 | H9: 재.관 | I9: U/S | J9: 단위 | K9: 소요량 | L9: 단가 | M9: 금액 | N9: 재 질 | P9: LOSS율 | Q9: 재.관 | R9: U/S | S9: 단위 | T9: 소요량 | U9: 단가 | V9: 금액 | W9: 재 질 | Y9: LOSS율 | Z9: 재.관 | AA9: U/S | AB9: 단위 | AC9: 소요량 | AD9: 단가 | AE9: 금액 | AH9: ※년 생산 50,000대
A10: ①
A11: 재 | B11: GANH ASY RASPAD D/SIDE | C11: 55591-10000 | D11: 사출 | E11: MS215-08 TB | G11: 0.0051220802 | H11: 0.021555882 | I11: 2 | J11: g | K11: 54.213044 | L11: 4.0889472 | M11: =ROUNDDOWN(L11*K11*(1+G11),2) -> 222.8 | N11: MS214-04 TA | P11: 0.0050867212 | Q11: 0.023329312 | R11: 1 | S11: g | T11: 25.06559 | U11: 4.4683817 | V11: =ROUNDDOWN(U11*T11*(1+981),2) -> 109986.57 | W11: MS215-08 TB | Y11: 0.005027475 | Z11: 0.01970384 | AA11: 1 | AB11: g | AC11: 45.990048 | AD11: 4.5884894 | AE11: =ROUNDDOWN(AD11*AC11*(1+Y11),2) -> 212.08 | AF11: =IF(AE11-M11=0," ",AE11-M11) -> -10.72 | AG11: =IF(AE11-V11=0," ",AE11-V11) -> -109774.49 | AH11: ▶ MS SPEC 표준가 미결정
A12: 료 | B12: B/S | D12: 분쇄비 | E12: PC+PBT | G12: 0 | H12: 0.016444748 | I12: 1 | J12: g | K12: =K11*(22/100) -> 11.92687 | L12: 0.046425813 | M12: =ROUNDDOWN(L12*K12*(1+G12),2) -> 0.55 | N12: PC+PBT | P12: 0 | Q12: 0.016707759 | R12: 3 | S12: g | T12: =T11*(22/100) -> 5.5144299 | U12: 0.031189275 | V12: =ROUNDDOWN(U12*T12*(1+982),2) -> 169.06 | W12: PC+PBT | Y12: 0 | Z12: 0.019919158 | AA12: 1 | AB12: g | AC12: =AC11*(22/100) -> 10.117811 | AD12: 0.035632212 | AE12: =ROUNDDOWN(AD12*AC12*(1+Y12),2) -> 0.36 | AF12: =IF(AE12-M12=0," ",AE12-M12) -> -0.19 | AG12: =IF(AE12-V12=0," ",AE12-V12) -> -168.7 | AH12: - 롯데첨단소재 견적가 적용
A13: 비 | AF13: =IF(AE13-M13=0," ",AE13-M13) | AG13: =IF(AE13-V13=0," ",AE13-V13)
B14: GANH ASY RASPAD D/SIDE | C14: 55591-10000 | D14: 일반부품 | N14: MOBIS 사급 | P14: 0 | Q14: 0.0083137805 | R14: 4 | S14: EA | T14: 2 | U14: 992 | V14: =ROUNDDOWN(U14*T14*(R14),2) -> 7936 | AH14: ▶옵션사양 변경 (사급부품 → 메탈도장) , 입찰당시 사급가 적용
B15: GANH ASY RASPAD D/SIDE 도장재료비 | C15: 55591-10000 | D15: 도장재료비 | E15: 메탈도장 | G15: 0 | H15: 0.023508361 | I15: 2 | J15: d㎡ | K15: 1.4783838 | L15: ='1-1. 도장재료비'!J21 -> 564.27 | M15: =ROUNDDOWN((L15*K15*(1+G15)*I15),2) -> 1668.41 | W15: 메탈도장 | Y15: 0 | Z15: 0.019123772 | AA15: 1 | AB15: d㎡ | AC15: 1.4588135 | AD15: ='1-1. 도장재료비'!J21 -> 564.27 | AE15: =ROUNDDOWN((AD15*AC15*(1+Y15)*AA15),2) -> 823.16 | AF15: =IF(AE15-M15=0," ",AE15-M15) -> -845.25 | AG15: =IF(AE15-V15=0," ",AE15-V15) -> 823.16 | AH15: └ 1-1. 도장재료비 참조
B16: GANH ASY RASPAD D/SIDE 도장가공비 | C16: 55591-10000 | D16: 도장가공비 | E16: MS655-11 TC | G16: 0 | H16: 0 | I16: 1 | J16: EA | K16: 10 | L16: ='1-2. 도장가공비'!O19 -> 4482.7548 | M16: =ROUNDDOWN((L16/K16*(1+G16)*I16),2) -> 448.27 | W16: MS655-11 TC | Y16: 0 | Z16: 0 | AA16: 2 | AB16: EA | AC16: 5 | AD16: ='1-2. 도장가공비'!O19 -> 4482.7548 | AE16: =ROUNDDOWN((AD16/AC16*(1+Y16)*AA16),2) -> 1793.1 | AF16: =IF(AE16-M16=0," ",AE16-M16) -> 1344.83 | AG16: =IF(AE16-V16=0," ",AE16-V16) -> 1793.1 | AH16: └1-2. 도장가공비 참조
B17: GANH ASY RASPAD D/SIDE 도장폐기비 | C17: 55591-10000 | D17: 도장폐기비 | G17: 0 | H17: 0 | I17: 1 | J17: EA | K17: =((M11+M12+M29+M36)*3%)-((K11*3%)/1000*400) -> 16.328843 | L17: 1 | M17: =ROUNDDOWN((L17*K17*(1+G17)*I17),2) -> 16.32 | Y17: 0 | Z17: 0 | AA17: 1 | AB17: EA | AC17: =((AE11+AE12+AE29+AE36)*3%)-((AC11*3%)/1000*400) -> 9.6994194 | AD17: 1 | AE17: =ROUNDDOWN((AD17*AC17*(1+Y17)*AA17),2) -> 9.69 | AF17: =IF(AE17-M17=0," ",AE17-M17) -> -6.63 | AG17: =IF(AE17-V17=0," ",AE17-V17) -> 9.69
AF18: =IF(AE18-M18=0," ",AE18-M18) | AG18: =IF(AE18-V18=0," ",AE18-V18)
B19: PLACTIC CILP | C19: 55547-2L000 | D19: C/O | G19: 0 | H19: 0.0093267777 | I19: 1 | J19: EA | K19: 1 | L19: 72 | M19: =ROUNDDOWN(L19*K19*(I19),2) -> 72 | P19: 0 | Q19: 0.011863134 | R19: 6 | S19: EA | T19: 5 | U19: 15 | V19: =ROUNDDOWN(U19*T19*(R19),2) -> 450 | Y19: 0 | Z19: 0.0087676899 | AA19: 2 | AB19: EA | AC19: 1 | AD19: 22 | AE19: =ROUNDDOWN(AD19*AC19*(AA19),2) -> 44 | AF19: =IF(AE19-M19=0," ",AE19-M19) -> -28 | AG19: =IF(AE19-V19=0," ",AE19-V19) -> -406 | AH19: ▶ 입찰당시 H/W 단가 적용 → 현재 인정가 적용
B20: PAD ANTINOSE NO.3 | C20: 84520-98020 | D20: 일반부품 | E20: 흑색부직포(10*10*0.5T) | G20: 0 | H20: 0 | I20: 6 | J20: EA | K20: 2 | L20: ='1-4 PAD'!V10 -> 23.7 | M20: =ROUNDDOWN(L20*K20*(I20),2) -> 284.4 | N20: 흑색부직포(22*15*0.5T) | P20: 0 | Q20: 0 | R20: 40 | S20: EA | T20: 2 | U20: 8.9144472 | V20: =ROUNDDOWN(U20*T20*(R20),2) -> 713.15 | W20: 흑색부직포(10*10*0.5T) | Y20: 0 | Z20: 0 | AA20: 12 | AB20: EA | AC20: 1 | AD20: ='1-4 PAD'!V10 -> 23.7 | AE20: =ROUNDDOWN(AD20*AC20*(AA20),2) -> 284.4 | AF20: =IF(AE20-M20=0," ",AE20-M20) | AG20: =IF(AE20-V20=0," ",AE20-V20) -> -428.75 | AH20: ▶1-4.PAD 참조 (입찰기준 적용기준 변경 18년 → 21년)
B21: PAD ANTINOSE NO.5 | C21: 55596-98020 | D21: 일반부품 | E21: 흑색부직포(50*15*0.5T) | G21: 0 | H21: 0 | I21: 1 | J21: EA | K21: 3 | L21: ='1-4 PAD'!V11 -> 24.4 | M21: =ROUNDDOWN(L21*K21*(I21),2) -> 73.2 | W21: 흑색부직포(50*15*0.5T) | Y21: 0 | Z21: 0 | AA21: 1 | AB21: EA | AC21: 1 | AD21: ='1-4 PAD'!V11 -> 24.4 | AE21: =ROUNDDOWN(AD21*AC21*(AA21),2) -> 24.4 | AF21: =IF(AE21-M21=0," ",AE21-M21) -> -48.8 | AG21: =IF(AE21-V21=0," ",AE21-V21) -> 24.4 | AH21: ↑
B22: PAD ANTINOSE NO.7 | C22: 55591-98110 | D22: 일반부품 | E22: 흑색부직포(25*15*0.5T) | G22: 0 | H22: 0 | I22: 2 | J22: EA | K22: 2 | L22: ='1-4 PAD'!V12 -> 17.5 | M22: =ROUNDDOWN(L22*K22*(I22),2) -> 70 | W22: 흑색부직포(25*15*0.5T) | Y22: 0 | Z22: 0 | AA22: 2 | AB22: EA | AC22: 2 | AD22: ='1-4 PAD'!V12 -> 17.5 | AE22: =ROUNDDOWN(AD22*AC22*(AA22),2) -> 70 | AF22: =IF(AE22-M22=0," ",AE22-M22) | AG22: =IF(AE22-V22=0," ",AE22-V22) -> 70 | AH22: ↑
B23: BAR CODE | D23: 일반부품 | G23: 0 | H23: 0 | I23: 1 | J23: EA | K23: 3 | L23: 148 | M23: =ROUNDDOWN(L23*K23*(I23),2) -> 444 | Y23: 0 | Z23: 0 | AA23: 2 | AB23: EA | AC23: 2 | AD23: 77 | AE23: =ROUNDDOWN(AD23*AC23*(AA23),2) -> 308 | AF23: =IF(AE23-M23=0," ",AE23-M23) -> -136 | AG23: =IF(AE23-V23=0," ",AE23-V23) -> 308 | AH23: ▶ 입찰 比 바코드 부착 도면명기 (사양추가)
B24: 보호랩 | C24: 237*46 | D24: 일반부품 | G24: 0 | H24: 0 | I24: 2 | J24: EA | K24: 1 | L24: ='#보호랩'!O6 -> 95 | M24: =ROUNDDOWN(L24*K24*(I24),2) -> 190 | Y24: 0 | Z24: 0 | AA24: 1 | AB24: EA | AC24: 1 | AD24: ='#보호랩'!O6 -> 95 | AE24: =ROUNDDOWN(AD24*AC24*(AA24),2) -> 95 | AF24: =IF(AE24-M24=0," ",AE24-M24) -> -95 | AG24: =IF(AE24-V24=0," ",AE24-V24) -> 95 | AH24: ▶ 생산공장 요청사항 반영 보호랩 적용
AF25: =IF(AE25-M25=0," ",AE25-M25) | AG25: =IF(AE25-V25=0," ",AE25-V25)
B26: 재료비 소계 | M26: =SUM(M10:M25) -> 3489.95 | V26: =SUM(V10:V25) -> 119254.78 | AE26: =SUM(AE10:AE25) -> 3664.19 | AF26: =IF(AE26-M26=0," ",AE26-M26) -> 174.24 | AG26: =IF(AE26-V26=0," ",AE26-V26) -> -115590.59
E27: 준비시간 | F27: LOT | G27: U/S | H27: 일.관 | I27: C/V | J27: 인원 | K27: C/T | L27: 임율 | M27: 금액 | N27: 준비시간 | O27: LOT | P27: U/S | Q27: 일.관 | R27: C/V | S27: 인원 | T27: C/T | U27: 임율 | V27: 금액 | W27: 준비시간 | X27: LOT | Y27: U/S | Z27: 일.관 | AA27: C/V | AB27: 인원 | AC27: C/T | AD27: 임율 | AE27: 금액
A28: ② | AF28: =IF(AE28-M28=0," ",AE28-M28) | AG28: =IF(AE28-V28=0," ",AE28-V28) | AJ28: 조립공수 | AL28: AA 초도가 제출 | AO28: 입찰가 | AR28: 초도가 | AU28: 비고
A29: 노 | B29: GANH ASY RASPAD D/SIDE | C29: 55591-10000 | D29: 사출 | E29: 74 | F29: 4386 | G29: 1 | H29: 0.22352822 | I29: 3 | J29: 0.47305096 | K29: =ROUNDDOWN(16+(4.396*((K11+K12)*I29)^0.1477)+3.22*3^2*1*0.9,2) -> 51.68 | L29: 79889 | M29: =ROUNDDOWN((K29/I29*1.1+E29*60/F29)*L29/3600*J29,2) -> 209.55 | N29: 66 | O29: 18375 | P29: 2 | Q29: 0.28480919 | R29: 8 | S29: 0.65811303 | T29: 57.874329 | U29: 41073 | V29: =ROUNDDOWN((T29/R29*1.1+N29*60/O29)*U29/3600*S29,2) -> 61.36 | W29: 223 | X29: 5844 | Y29: 2 | Z29: 0.21208323 | AA29: 5 | AB29: 0.42292466 | AC29: =ROUNDDOWN(16+(4.396*((AC11+AC12)*AA29)^0.1477)+3.22*3^2*1*0.9,2) -> 52.18 | AD29: 49561 | AE29: =ROUNDDOWN((AC29/AA29*1.1+W29*60/X29)*AD29/3600*AB29,2) -> 80.16 | AF29: =IF(AE29-M29=0," ",AE29-M29) -> -129.39 | AG29: =IF(AE29-V29=0," ",AE29-V29) -> 18.8 | AH29: ▶ 입찰기준 연동 (입찰기준 임율 20,700 比 -15.9% 적용) | AJ29: NO | AK29: P/NO | AL29: U/S | AM29: C/T | AN29: 총공수 | AO29: U/S | AP29: C/T | AQ29: 총공수 | AR29: U/S | AS29: C/T | AT29: 총공수
A30: 무 | B30: ASSY | C30: 55591-10000 | D30: ASS'Y | E30: 0 | F30: 3808 | G30: 1 | H30: 0.21492457 | I30: =IF($D30="ASS'Y",1,VLOOKUP($C30,#REF!,22,0)) -> 1 | J30: 1 | K30: =AN35 -> 141 | L30: 61584 | M30: =ROUNDDOWN((K30/I30*1.1+E30*60/F30)*L30/3600*J30,2) -> 2653.24 | N30: 0 | O30: 10868 | P30: 2 | Q30: 0.19112386 | R30: =IF($D30="ASS'Y",1,VLOOKUP($C30,#REF!,22,0)) -> 1 | S30: 1 | T30: =AQ35 -> 31 | U30: 76597 | V30: =ROUNDDOWN((T30/R30*1.1+N30*60/O30)*U30/3600*S30,2) -> 725.54 | W30: 0 | X30: 5805 | Y30: 2 | Z30: 0.21176507 | AA30: =IF($D30="ASS'Y",1,VLOOKUP($C30,#REF!,22,0)) -> 1 | AB30: 2 | AC30: =AT35 -> 147 | AD30: 46176 | AE30: =ROUNDDOWN((AC30/AA30*1.1+W30*60/X30)*AD30/3600*AB30,2) -> 4148.14 | AF30: =IF(AE30-M30=0," ",AE30-M30) -> 1494.9 | AG30: =IF(AE30-V30=0," ",AE30-V30) -> 3422.6 | AH30: ▶ 입찰 比 H/W 및 PAD U/S 증가에 따른 조립시간 적용 | AJ30: 1 | AK30: PLACTIC CILP | AL30: =I19 -> 1 | AM30: 6 | AN30: =AL30*AM30 -> 6 | AO30: 2 | AP30: 3 | AQ30: =AO30*AP30 -> 6 | AR30: =AA19 -> 2 | AS30: 4 | AT30: =AR30*AS30 -> 8
A31: 비 | B31: 사상 | E31: 0 | F31: 3986 | G31: 2 | H31: 0.29967714 | I31: 1 | J31: 1 | K31: =13*('1-6. 사상'!O5)/1000 -> 9.1152225 | L31: 98186 | M31: =ROUNDDOWN((K31/I31*1.1+E31*60/F31)*L31/3600*J31,2) -> 273.46 | W31: 0 | X31: 6375 | Y31: 1 | Z31: 0.21321681 | AA31: 2 | AB31: 2 | AC31: =13*('1-6. 사상'!O5)/1000 -> 9.1152225 | AD31: 36242 | AE31: =ROUNDDOWN((AC31/AA31*1.1+W31*60/X31)*AD31/3600*AB31,2) -> 100.94 | AF31: =IF(AE31-M31=0," ",AE31-M31) -> -172.52 | AG31: =IF(AE31-V31=0," ",AE31-V31) -> 100.94 | AH31: ▶ 1-6. 사상 참조 (도면 명기 사상공수 반영) | AJ31: 2 | AK31: PAD ANTINOSE NO.3 | AL31: =I20 -> 6 | AM31: 7 | AN31: =AL31*AM31 -> 42 | AO31: 5 | AP31: 5 | AQ31: =AO31*AP31 -> 25 | AR31: =AA20 -> 12 | AS31: 7 | AT31: =AR31*AS31 -> 84
AF32: =IF(AE32-M32=0," ",AE32-M32) | AG32: =IF(AE32-V32=0," ",AE32-V32) | AJ32: 3 | AK32: PAD ANTINOSE NO.5 | AL32: =I21 -> 1 | AM32: 54 | AN32: =AL32*AM32 -> 54 | AR32: =AA21 -> 1 | AS32: 9 | AT32: =AR32*AS32 -> 9
B33: 노무비 소계 | M33: =SUM(M28:M32) -> 3136.25 | V33: =SUM(V28:V32) -> 786.9 | AE33: =SUM(AE28:AE32) -> 4329.24 | AF33: =IF(AE33-M33=0," ",AE33-M33) -> 1192.99 | AG33: =IF(AE33-V33=0," ",AE33-V33) -> 3542.34 | AJ33: 4 | AK33: PAD ANTINOSE NO.7 | AL33: =I22 -> 2 | AM33: 5 | AN33: =AL33*AM33 -> 10 | AR33: =AA22 -> 2 | AS33: 2 | AT33: =AR33*AS33 -> 4
E34: 준비시간 | F34: LOT | G34: U/S | H34: 일.관 | I34: C/V | J34: 기종 | K34: C/T | L34: 경비 | M34: 금액 | N34: 준비시간 | O34: LOT | P34: U/S | Q34: 일.관 | R34: C/V | S34: 기종 | T34: C/T | U34: 경비 | V34: 금액 | W34: 준비시간 | X34: LOT | Y34: U/S | Z34: 일.관 | AA34: C/V | AB34: 기종 | AC34: C/T | AD34: 경비 | AE34: 금액 | AJ34: 5 | AK34: 검사 | AL34: =I23 -> 1 | AM34: 17 | AN34: =AL34*AM34 -> 17 | AR34: =AA23 -> 2 | AS34: 15 | AT34: =AR34*AS34 -> 30
A35: ③ | AF35: =IF(AE35-M35=0," ",AE35-M35) | AG35: =IF(AE35-V35=0," ",AE35-V35) | AJ35: 소계 | AL35: =SUM(AL30:AL33) -> 10 | AM35: =SUM(AM30:AM33) -> 72 | AN35: =SUM(AN30:AN34)+12 -> 141 | AO35: =SUM(AO30:AO33) -> 7 | AP35: =SUM(AP30:AP33) -> 8 | AQ35: =SUM(AQ30:AQ34) -> 31 | AR35: =SUM(AR30:AR33) -> 17 | AS35: =SUM(AS30:AS33) -> 22 | AT35: =SUM(AT30:AT34)+12 -> 147 | AU35: D/SIDE 12초
A36: 경 | B36: GANH ASY RASPAD D/SIDE | C36: 55591-10000 | D36: 사출 | E36: 83 | F36: 3430 | G36: 1 | H36: 0.26191876 | I36: 3 | J36: 642 | K36: =K29 -> 51.68 | L36: 14678 | M36: =ROUNDDOWN(L36*1.6/3600*(K36*1.1/I36+E36*60/F36)*G36,2) -> 133.08 | N36: 121 | O36: 15425 | P36: 3 | Q36: 0.22554614 | R36: 6 | S36: 156 | T36: =T29 -> 57.874329 | U36: 4568 | V36: =ROUNDDOWN(U36*1.55/3600*(T36*1.1/R36+N36*60/O36)*P36,2) -> 65.38 | W36: 101 | X36: 10727 | Y36: 1 | Z36: 0.19277574 | AA36: 4 | AB36: 623 | AC36: =AC29 -> 52.18 | AD36: 7409 | AE36: =ROUNDDOWN(AD36*1.6/3600*(AC36*1.1/AA36+W36*60/X36)*Y36,2) -> 49.11 | AF36: =IF(AE36-M36=0," ",AE36-M36) -> -83.97 | AG36: =IF(AE36-V36=0," ",AE36-V36) -> -16.27 | AH36: ▶ 제품형상 및 원재료특성에 따른 형체력 적용
A37: 비 | AF37: =IF(AE37-M37=0," ",AE37-M37) | AG37: =IF(AE37-V37=0," ",AE37-V37)
AF38: =IF(AE38-M38=0," ",AE38-M38) | AG38: =IF(AE38-V38=0," ",AE38-V38)
B39: 경비 소계 | M39: =SUM(M35:M38) -> 133.08 | V39: =SUM(V35:V38) -> 65.38 | AE39: =SUM(AE35:AE38) -> 49.11 | AF39: =IF(AE39-M39=0," ",AE39-M39) -> -83.97 | AG39: =IF(AE39-V39=0," ",AE39-V39) -> -16.27
A40: ④ | B40: 가 공 비 | I40: ②+③ | M40: =M39+M33 -> 3269.33 | R40: ②+③ | V40: =V39+V33 -> 852.28 | AA40: ②+③ | AE40: =AE39+AE33 -> 4378.35 | AF40: =IF(AE40-M40=0," ",AE40-M40) -> 1109.02 | AG40: =IF(AE40-V40=0," ",AE40-V40) -> 3526.07
A41: ⑤ | B41: 제 조 원 가 | I41: ①+④ | M41: =M40+M26 -> 6759.28 | R41: ①+④ | V41: =V40+V26 -> 120107.06 | AA41: ①+④ | AE41: =AE40+AE26 -> 8042.54 | AF41: =IF(AE41-M41=0," ",AE41-M41) -> 1283.26 | AG41: =IF(AE41-V41=0," ",AE41-V41) -> -112064.52
A42: ⑥ | B42: 일 반 관 리 비 | I42: ④* | L42: 0.26820632 | M42: =SUMPRODUCT(H28:H38,M28:M38) -> 733.89267 | R42: ④* | U42: 0.18359558 | V42: =SUMPRODUCT(Q28:Q38,V28:V38) -> 170.89011 | AA42: ④* | AD42: 0.24708462 | AE42: =SUMPRODUCT(Z28:Z38,AE28:AE38) -> 926.42109 | AF42: =IF(AE42-M42=0," ",AE42-M42) -> 192.52841 | AG42: =IF(AE42-V42=0," ",AE42-V42) -> 755.53098 | AH42: ▶ 입찰기준 연동 (재료관리비 25% → 22% 적용)
A43: ⑦ | B43: 이 윤 | I43: (④+⑥)* | L43: 0.14340263 | M43: =ROUNDDOWN((M40+M42)*L43,2) -> 574.07 | R43: (④+⑥)* | U43: 0.11004863 | V43: =ROUNDDOWN((V40+V42)*U43,2) -> 112.59 | AA43: (④+⑥)* | AD43: 0.082634041 | AE43: =ROUNDDOWN((AE40+AE42)*AD43,2) -> 438.35 | AF43: =IF(AE43-M43=0," ",AE43-M43) -> -135.72 | AG43: =IF(AE43-V43=0," ",AE43-V43) -> 325.76 | AH43: ▶ 입찰기준 연동 (이윤 15% → 10% 적용)
...

Sheet 55648-98855
A1: 비 교 원 가 계 산 서
A3: 품 번 : 55648-98855 | AH3: 차 종 : qq5
A4: 품 명 : GANH ASY RASPAD D/SIDE (RHD) | AH4: 업 체 : 지-텍텍텍(DDDD)
A5: EO NO : ABC564 | AH5: 작성일자 : 22.1.21
A7: 구 분 | E7: T 초도가 제출 (A) | N7: 55648-98655 결정가 (A) | W7: 초도가 (B) | AF7: 차이 (B-A) | AG7: 차이 (B-A) | AH7: 비 고
E9: 재 질 | G9: LOSS율 | H9: 재.관 | I9: U/S | J9: 단위 | K9: 소요량 | L9: 단가 | M9: 금액 | N9: 재 질 | P9: LOSS율 | Q9: 재.관 | R9: U/S | S9: 단위 | T9: 소요량 | U9: 단가 | V9: 금액 | W9: 재 질 | Y9: LOSS율 | Z9: 재.관 | AA9: U/S | AB9: 단위 | AC9: 소요량 | AD9: 단가 | AE9: 금액 | AH9: ※년 생산 5,000대
A10: ①
A11: 재 | B11: GANH ASY RASPAD D/SIDE | C11: 55591-98500 | D11: 사출 | E11: MS215-08 TB | G11: 0.017910056 | H11: 0.019467657 | I11: 2 | J11: g | K11: 40.572522 | L11: 5.3490552 | M11: =ROUNDDOWN(L11*K11*(1+G11),2) -> 220.91 | N11: MS215-08 TB | P11: 0.0046956654 | Q11: 0.016835458 | R11: 1 | S11: g | T11: 39.733642 | U11: 4.9180667 | V11: =ROUNDDOWN(U11*T11*(1+981),2) -> 191895.27 | W11: MS215-08 TB | Y11: 0.022490459 | Z11: 0.020336234 | AA11: 1 | AB11: g | AC11: 56.855015 | AD11: 4.4835042 | AE11: =ROUNDDOWN(AD11*AC11*(1+Y11),2) -> 260.64 | AF11: =IF(AD11-L11=0," ",AD11-L11) -> -0.86555105 | AG11: =IF(AE11-V11=0," ",AE11-V11) -> -191634.63 | AH11: ▶ LOSS율 차이 / 제품중량 차이 적용
A12: 료 | B12: B/S | D12: 분쇄비 | E12: PC+PBT | G12: 0 | H12: 0.01903193 | I12: 1 | J12: g | K12: =K11*(22/100) -> 8.9259547 | L12: 0.03285365 | M12: =ROUNDDOWN(L12*K12*(1+G12),2) -> 0.29 | N12: PC+PBT | P12: 0 | Q12: 0.020026969 | R12: 1 | S12: g | T12: =T11*(22/100) -> 8.7414013 | U12: 0.036248484 | V12: =ROUNDDOWN(U12*T12*(1+982),2) -> 311.47 | W12: PC+PBT | Y12: 0 | Z12: 0.023722916 | AA12: 2 | AB12: g | AC12: =AC11*(22/100) -> 12.508103 | AD12: 0.041892539 | AE12: =ROUNDDOWN(AD12*AC12*(1+Y12),2) -> 0.52 | AF12: =IF(AD12-L12=0," ",AD12-L12) -> 0.0090388899 | AG12: =IF(AE12-V12=0," ",AE12-V12) -> -310.95 | AH12: ↑
A13: 비 | AF13: =IF(AD13-L13=0," ",AD13-L13) | AG13: =IF(AE13-V13=0," ",AE13-V13)
AG14: =IF(AE14-V14=0," ",AE14-V14)
B15: GANH ASY RASPAD D/SIDE 도장재료비 | C15: 55591-98500 | D15: 도장재료비 | E15: 메탈도장 | G15: 0 | H15: 0.021258051 | I15: 1 | J15: d㎡ | K15: 1.4111291 | L15: ='1-1. 도장재료비'!J21 -> 564.27 | M15: =ROUNDDOWN((L15*K15*(1+G15)*I15),2) -> 796.25 | N15: 메탈도장 | P15: 0 | Q15: 0.016515929 | R15: 2 | S15: d㎡ | T15: 1.4150695 | U15: =AD15 -> 564.27 | V15: =ROUNDDOWN((U15*T15*(1+985)*R15),2) -> 1574605.1 | W15: 메탈도장 | Y15: 0 | Z15: 0.019976568 | AA15: 1 | AB15: d㎡ | AC15: 1.1652385 | AD15: ='1-1. 도장재료비'!J21 -> 564.27 | AE15: =ROUNDDOWN((AD15*AC15*(1+Y15)*AA15),2) -> 657.5 | AF15: =IF(AD15-L15=0," ",AD15-L15) | AG15: =IF(AE15-V15=0," ",AE15-V15) -> -1573947.6
B16: GANH ASY RASPAD D/SIDE 도장가공비 | C16: 55591-98500 | D16: 도장가공비 | E16: MS655-11 TC | G16: 0 | H16: 0 | I16: 1 | J16: EA | K16: 5 | L16: ='1-2. 도장가공비'!O19 -> 4482.7548 | M16: =ROUNDDOWN((L16/K16*(1+G16)*I16),2) -> 896.55 | N16: MS655-11 TC | P16: 0 | Q16: 0 | R16: 1 | S16: EA | T16: 4 | U16: =AD16 -> 4482.7548 | V16: =ROUNDDOWN((U16/T16*(1+986)*R16),2) -> 1106119.7 | W16: MS655-11 TC | Y16: 0 | Z16: 0 | AA16: 2 | AB16: EA | AC16: 5 | AD16: ='1-2. 도장가공비'!O19 -> 4482.7548 | AE16: =ROUNDDOWN((AD16/AC16*(1+Y16)*AA16),2) -> 1793.1 | AF16: =IF(AD16-L16=0," ",AD16-L16) | AG16: =IF(AE16-V16=0," ",AE16-V16) -> -1104326.6
B17: GANH ASY RASPAD D/SIDE 도장폐기비 | C17: 55591-98500 | D17: 도장폐기비 | G17: 0 | H17: 0 | I17: 1 | J17: EA | K17: =((M11+M12+M29+M36)*3%)-((K11*3%)/1000*400) -> 10.28013 | L17: 2 | M17: =ROUNDDOWN((L17*K17*(1+G17)*I17),2) -> 20.56 | P17: 0 | Q17: 0 | R17: 2 | S17: EA | T17: =((V11+V12+V29+V36)*3%)-((T11*3%)/1000*400) -> 5769.3353 | U17: =AD17 -> 2 | V17: =ROUNDDOWN((U17*T17*(1+987)*R17),2) -> 22800413 | Y17: 0 | Z17: 0 | AA17: 2 | AB17: EA | AC17: =((AE11+AE12+AE29+AE36)*3%)-((AC11*3%)/1000*400) -> 15.01764 | AD17: 2 | AE17: =ROUNDDOWN((AD17*AC17*(1+Y17)*AA17),2) -> 60.07 | AF17: =IF(AD17-L17=0," ",AD17-L17) | AG17: =IF(AE17-V17=0," ",AE17-V17) -> -22800353 | AH17: ▶ LOSS율 차이 / 제품중량 차이 적용
AF18: =IF(AD18-L18=0," ",AD18-L18) | AG18: =IF(AE18-V18=0," ",AE18-V18)
B19: PLACTIC CILP | C19: 55547-2L000 | D19: C/O | G19: 0 | H19: 0.011503119 | I19: 1 | J19: EA | K19: 1 | L19: 37 | M19: =ROUNDDOWN(L19*K19*(I19),2) -> 37 | P19: 0 | Q19: 0.011189189 | R19: 2 | S19: EA | T19: 1 | U19: 13 | V19: =ROUNDDOWN(U19*T19*(R19),2) -> 26 | Y19: 0 | Z19: 0.0086710513 | AA19: 1 | AB19: EA | AC19: 2 | AD19: 23 | AE19: =ROUNDDOWN(AD19*AC19*(AA19),2) -> 46 | AF19: =IF(AD19-L19=0," ",AD19-L19) -> -14 | AG19: =IF(AE19-V19=0," ",AE19-V19) -> 20
B20: PAD ANTINOSE NO.3 | C20: 84520-98020 | D20: 일반부품 | E20: 흑색부직포(10*10*0.5T) | G20: 0 | H20: 0 | I20: 6 | J20: EA | K20: 1 | L20: 16.069725 | M20: =ROUNDDOWN(L20*K20*(I20),2) -> 96.41 | N20: 흑색부직포(10*10*0.5T) | P20: 0 | Q20: 0 | R20: 13 | S20: EA | T20: 1 | U20: =AD20 -> 23.7 | V20: =ROUNDDOWN(U20*T20*(R20),2) -> 308.1 | W20: 흑색부직포(10*10*0.5T) | Y20: 0 | Z20: 0 | AA20: 6 | AB20: EA | AC20: 2 | AD20: ='1-4 PAD'!V10 -> 23.7 | AE20: =ROUNDDOWN(AD20*AC20*(AA20),2) -> 284.4 | AF20: =IF(AD20-L20=0," ",AD20-L20) -> 7.6302755 | AG20: =IF(AE20-V20=0," ",AE20-V20) -> -23.7
B21: PAD ANTINOSE NO.5 | C21: 55596-98020 | D21: 일반부품 | E21: 흑색부직포(50*15*0.5T) | G21: 0 | H21: 0 | I21: 1 | J21: EA | K21: 1 | L21: 28.262494 | M21: =ROUNDDOWN(L21*K21*(I21),2) -> 28.26 | N21: 흑색부직포(50*15*0.5T) | P21: 0 | Q21: 0 | R21: 1 | S21: EA | T21: 1 | U21: =AD21 -> 24.4 | V21: =ROUNDDOWN(U21*T21*(R21),2) -> 24.4 | W21: 흑색부직포(50*15*0.5T) | Y21: 0 | Z21: 0 | AA21: 1 | AB21: EA | AC21: 2 | AD21: ='1-4 PAD'!V11 -> 24.4 | AE21: =ROUNDDOWN(AD21*AC21*(AA21),2) -> 48.8 | AF21: =IF(AD21-L21=0," ",AD21-L21) -> -3.8624943 | AG21: =IF(AE21-V21=0," ",AE21-V21) -> 24.4
B22: PAD ANTINOSE NO.7 | C22: 55591-98110 | D22: 일반부품 | E22: 흑색부직포(25*15*0.5T) | G22: 0 | H22: 0 | I22: 4 | J22: EA | K22: 1 | L22: 18.446954 | M22: =ROUNDDOWN(L22*K22*(I22),2) -> 73.78 | N22: 흑색부직포(25*15*0.5T) | P22: 0 | Q22: 0 | R22: 5 | S22: EA | T22: 2 | U22: =AD22 -> 17.5 | V22: =ROUNDDOWN(U22*T22*(R22),2) -> 175 | W22: 흑색부직포(25*15*0.5T) | Y22: 0 | Z22: 0 | AA22: 5 | AB22: EA | AC22: 2 | AD22: ='1-4 PAD'!V12 -> 17.5 | AE22: =ROUNDDOWN(AD22*AC22*(AA22),2) -> 175 | AF22: =IF(AD22-L22=0," ",AD22-L22) -> -0.94695443 | AG22: =IF(AE22-V22=0," ",AE22-V22)
B23: BAR CODE | D23: 일반부품 | G23: 0 | H23: 0 | I23: 1 | J23: EA | K23: 2 | L23: 75 | M23: =ROUNDDOWN(L23*K23*(I23),2) -> 150 | P23: 0 | Q23: 0 | R23: 1 | S23: EA | T23: 1 | U23: 84 | V23: =ROUNDDOWN(U23*T23*(R23),2) -> 84 | Y23: 0 | Z23: 0 | AA23: 1 | AB23: EA | AC23: 2 | AD23: 134 | AE23: =ROUNDDOWN(AD23*AC23*(AA23),2) -> 268 | AF23: =IF(AD23-L23=0," ",AD23-L23) -> 59 | AG23: =IF(AE23-V23=0," ",AE23-V23) -> 184
B24: 보호랩 | C24: 237*46 | D24: 일반부품 | G24: 0 | H24: 0 | I24: 1 | J24: EA | K24: 2 | L24: 77 | M24: =ROUNDDOWN(L24*K24*(I24),2) -> 154 | P24: 0 | Q24: 0 | R24: 2 | S24: EA | T24: 2 | U24: =AD24 -> 95 | V24: =ROUNDDOWN(U24*T24*(R24),2) -> 380 | Y24: 0 | Z24: 0 | AA24: 1 | AB24: EA | AC24: 1 | AD24: ='#보호랩'!O6 -> 95 | AE24: =ROUNDDOWN(AD24*AC24*(AA24),2) -> 95 | AF24: =IF(AD24-L24=0," ",AD24-L24) -> 18 | AG24: =IF(AE24-V24=0," ",AE24-V24) -> -285
AF25: =IF(AD25-L25=0," ",AD25-L25) | AG25: =IF(AE25-V25=0," ",AE25-V25)
B26: 재료비 소계 | M26: =SUM(M10:M25) -> 2474.01 | V26: =SUM(V10:V25) -> 25674342 | AE26: =SUM(AE10:AE25) -> 3689.03 | AF26: =IF(AD26-L26=0," ",AD26-L26) | AG26: =IF(AE26-V26=0," ",AE26-V26) -> -25670653
E27: 준비시간 | F27: LOT | G27: U/S | H27: 일.관 | I27: C/V | J27: 인원 | K27: C/T | L27: 임율 | M27: 금액 | N27: 준비시간 | O27: LOT | P27: U/S | Q27: 일.관 | R27: C/V | S27: 인원 | T27: C/T | U27: 임율 | V27: 금액 | W27: 준비시간 | X27: LOT | Y27: U/S | Z27: 일.관 | AA27: C/V | AB27: 인원 | AC27: C/T | AD27: 임율 | AE27: 금액
A28: ② | AF28: =IF(AD28-L28=0," ",AD28-L28) | AG28: =IF(AE28-V28=0," ",AE28-V28)
A29: 노 | B29: GANH ASY RASPAD D/SIDE | C29: 55591-98500 | D29: 사출 | E29: 81 | F29: 1309 | G29: 2 | H29: 0.23122881 | I29: 5 | J29: 0.43035125 | K29: =ROUNDDOWN(16+(4.396*((K11+K12)*I29)^0.1477)+3.22*3^2*1*0.9,2) -> 52 | L29: 45249 | M29: =ROUNDDOWN((K29/I29*1.1+E29*60/F29)*L29/3600*J29,2) -> 81.96 | N29: 131 | O29: 2526 | P29: 2 | Q29: 0.18606129 | R29: 5 | S29: 0.52659516 | T29: =AC29 -> 51.19 | U29: 38259 | V29: =ROUNDDOWN((T29/R29*1.1+N29*60/O29)*U29/3600*S29,2) -> 80.43 | W29: 126 | X29: 1676 | Y29: 1 | Z29: 0.25169429 | AA29: 2 | AB29: 0.48776528 | AC29: =ROUNDDOWN(16+(4.396*((AC11+AC12)*AA29)^0.1477)+3.22*3^2*1*0.9,2) -> 51.19 | AD29: 43869 | AE29: =ROUNDDOWN((AC29/AA29*1.1+W29*60/X29)*AD29/3600*AB29,2) -> 194.15 | AF29: =IF(AD29-L29=0," ",AD29-L29) -> -1380 | AG29: =IF(AE29-V29=0," ",AE29-V29) -> 113.72 | AH29: ▶ 생산 LOT차이 | AJ29: 조립공수 | AL29: AA 초도가 제출 | AO29: 초도가 | AR29: 비고
A30: 무 | B30: ASSY | C30: 55591-98500 | D30: ASS'Y | E30: 0 | F30: 2535 | G30: 1 | H30: 0.23972436 | I30: =IF($D30="ASS'Y",1,VLOOKUP($C30,#REF!,22,0)) -> 1 | J30: 2 | K30: =AN36 -> 79 | L30: 31892 | M30: =ROUNDDOWN((K30/I30*1.1+E30*60/F30)*L30/3600*J30,2) -> 1539.67 | N30: 0 | O30: 3675 | P30: 1 | Q30: 0.18292638 | R30: =IF($D30="ASS'Y",1,VLOOKUP($C30,#REF!,22,0)) -> 1 | S30: 2 | T30: =AC30 -> 84 | U30: 21288 | V30: =ROUNDDOWN((T30/R30*1.1+N30*60/O30)*U30/3600*S30,2) -> 1092.78 | W30: 0 | X30: 3918 | Y30: 2 | Z30: 0.19638051 | AA30: =IF($D30="ASS'Y",1,VLOOKUP($C30,#REF!,22,0)) -> 1 | AB30: 2 | AC30: =AQ36 -> 84 | AD30: 46871 | AE30: =ROUNDDOWN((AC30/AA30*1.1+W30*60/X30)*AD30/3600*AB30,2) -> 2406.04 | AF30: =IF(AD30-L30=0," ",AD30-L30) -> 14979 | AG30: =IF(AE30-V30=0," ",AE30-V30) -> 1313.26 | AJ30: NO | AK30: P/NO | AL30: U/S | AM30: C/T | AN30: 총공수 | AO30: U/S | AP30: C/T | AQ30: 총공수
A31: 비 | B31: 사상 | E31: 0 | F31: 3200 | G31: 1 | H31: 0.27695068 | I31: 2 | J31: 1 | K31: =13*('1-6. 사상'!O5)/1000 -> 9.1152225 | L31: 28795 | M31: =ROUNDDOWN((K31/I31*1.1+E31*60/F31)*L31/3600*J31,2) -> 40.1 | N31: 0 | O31: 2808 | P31: 1 | Q31: 0.18943556 | R31: 2 | S31: 1 | T31: =AC31 -> 9.1152225 | U31: 24548 | V31: =ROUNDDOWN((T31/R31*1.1+N31*60/O31)*U31/3600*S31,2) -> 34.18 | W31: 0 | X31: 4054 | Y31: 2 | Z31: 0.19211069 | AA31: 2 | AB31: 1 | AC31: =13*('1-6. 사상'!O5)/1000 -> 9.1152225 | AD31: 17548 | AE31: =ROUNDDOWN((AC31/AA31*1.1+W31*60/X31)*AD31/3600*AB31,2) -> 24.43 | AF31: =IF(AD31-L31=0," ",AD31-L31) -> -11247 | AG31: =IF(AE31-V31=0," ",AE31-V31) -> -9.75 | AJ31: 1 | AK31: PLACTIC CILP | AL31: =I19 -> 1 | AM31: 2 | AN31: =AL31*AM31 -> 2 | AO31: =AA19 -> 1 | AP31: 2 | AQ31: =AO31*AP31 -> 2
AF32: =IF(AD32-L32=0," ",AD32-L32) | AG32: =IF(AE32-V32=0," ",AE32-V32) | AJ32: 2 | AK32: PAD ANTINOSE NO.3 | AL32: =I20 -> 6 | AM32: 5 | AN32: =AL32*AM32 -> 30 | AO32: =AA20 -> 6 | AP32: 5 | AQ32: =AO32*AP32 -> 30
B33: 노무비 소계 | M33: =SUM(M28:M32) -> 1661.73 | V33: =SUM(V28:V32) -> 1207.39 | AE33: =SUM(AE28:AE32) -> 2624.62 | AF33: =IF(AD33-L33=0," ",AD33-L33) | AG33: =IF(AE33-V33=0," ",AE33-V33) -> 1417.23 | AJ33: 3 | AK33: PAD ANTINOSE NO.5 | AL33: =I21 -> 1 | AM33: 5 | AN33: =AL33*AM33 -> 5 | AO33: =AA21 -> 1 | AP33: 5 | AQ33: =AO33*AP33 -> 5
E34: 준비시간 | F34: LOT | G34: U/S | H34: 일.관 | I34: C/V | J34: 기종 | K34: C/T | L34: 경비 | M34: 금액 | N34: 준비시간 | O34: LOT | P34: U/S | Q34: 일.관 | R34: C/V | S34: 기종 | T34: C/T | U34: 경비 | V34: 금액 | W34: 준비시간 | X34: LOT | Y34: U/S | Z34: 일.관 | AA34: C/V | AB34: 기종 | AC34: C/T | AD34: 경비 | AE34: 금액 | AJ34: 4 | AK34: PAD ANTINOSE NO.7 | AL34: =I22 -> 4 | AM34: 5 | AN34: =AL34*AM34 -> 20 | AO34: =AA22 -> 5 | AP34: 5 | AQ34: =AO34*AP34 -> 25
A35: ③ | AF35: =IF(AD35-L35=0," ",AD35-L35) | AG35: =IF(AE35-V35=0," ",AE35-V35) | AJ35: 5 | AK35: 검사 | AL35: =I23 -> 1 | AM35: 10 | AN35: =AL35*AM35 -> 10 | AO35: =AA23 -> 1 | AP35: 10 | AQ35: =AO35*AP35 -> 10
A36: 경 | B36: GANH ASY RASPAD D/SIDE | C36: 55591-98500 | D36: 사출 | E36: 83 | F36: 1230 | G36: 2 | H36: 0.28912794 | I36: 5 | J36: 338 | K36: =K29 -> 52 | L36: 4049 | M36: =ROUNDDOWN(L36*1.6/3600*(K36*1.1/I36+E36*60/F36)*G36,2) -> 55.74 | N36: 45 | O36: 2215 | P36: 1 | Q36: 0.1925556 | R36: 5 | S36: 686 | T36: =T29 -> 51.19 | U36: 7194 | V36: =ROUNDDOWN(U36*1.6/3600*(T36*1.1/R36+N36*60/O36)*P36,2) -> 39.9 | W36: 110 | X36: 1006 | Y36: 1 | Z36: 0.17848573 | AA36: 5 | AB36: 641 | AC36: =AC29 -> 51.19 | AD36: 8588 | AE36: =ROUNDDOWN(AD36*1.6/3600*(AC36*1.1/AA36+W36*60/X36)*Y36,2) -> 68.02 | AF36: =IF(AD36-L36=0," ",AD36-L36) -> 4539 | AG36: =IF(AE36-V36=0," ",AE36-V36) -> 28.12 | AH36: ▶ 생산 LOT차이 | AJ36: 소계 | AL36: =SUM(AL31:AL34) -> 12 | AM36: =SUM(AM31:AM34) -> 17 | AN36: =SUM(AN31:AN35)+12 -> 79 | AO36: =SUM(AO31:AO34) -> 13 | AP36: =SUM(AP31:AP34) -> 17 | AQ36: =SUM(AQ31:AQ35)+12 -> 84 | AR36: D/SIDE 12초
A37: 비 | AF37: =IF(AD37-L37=0," ",AD37-L37) | AG37: =IF(AE37-V37=0," ",AE37-V37)
AF38: =IF(AD38-L38=0," ",AD38-L38) | AG38: =IF(AE38-V38=0," ",AE38-V38)
B39: 경비 소계 | M39: =SUM(M35:M38) -> 55.74 | V39: =SUM(V35:V38) -> 39.9 | AE39: =SUM(AE35:AE38) -> 68.02 | AF39: =IF(AD39-L39=0," ",AD39-L39) | AG39: =IF(AE39-V39=0," ",AE39-V39) -> 28.12
A40: ④ | B40: 가 공 비 | I40: ②+③ | M40: =M39+M33 -> 1717.47 | R40: ②+③ | V40: =V39+V33 -> 1247.29 | AA40: ②+③ | AE40: =AE39+AE33 -> 2692.64 | AF40: =IF(AD40-L40=0," ",AD40-L40) | AG40: =IF(AE40-V40=0," ",AE40-V40) -> 1445.35
A41: ⑤ | B41: 제 조 원 가 | I41: ①+④ | M41: =M40+M26 -> 4191.48 | R41: ①+④ | V41: =V40+V26 -> 25675589 | AA41: ①+④ | AE41: =AE40+AE26 -> 6381.67 | AF41: =IF(AD41-L41=0," ",AD41-L41) | AG41: =IF(AE41-V41=0," ",AE41-V41) -> -25669208
A42: ⑥ | B42: 일 반 관 리 비 | I42: ④* | L42: 0.23326915 | M42: =SUMPRODUCT(H28:H38,M28:M38) -> 415.26963 | R42: ④* | U42: 0.21568292 | V42: =SUMPRODUCT(Q28:Q38,V28:V38) -> 229.02108 | AA42: ④* | AD42: 0.22484997 | AE42: =SUMPRODUCT(Z28:Z38,AE28:AE38) -> 538.19966 | AF42: =IF(AD42-L42=0," ",AD42-L42) -> -0.0084191825 | AG42: =IF(AE42-V42=0," ",AE42-V42) -> 309.17858
A43: ⑦ | B43: 이 윤 | I43: (④+⑥)* | L43: 0.16819982 | M43: =ROUNDDOWN((M40+M42)*L43,2) -> 358.72 | R43: (④+⑥)* | U43: 0.10255957 | V43: =ROUNDDOWN((V40+V42)*U43,2) -> 151.4 | AA43: (④+⑥)* | AD43: 0.088143291 | AE43: =ROUNDDOWN((AE40+AE42)*AD43,2) -> 284.77 | AF43: =IF(AD43-L43=0," ",AD43-L43) -> -0.080056527 | AG43: =IF(AE43-V43=0," ",AE43-V43) -> 133.37
...

Sheet 1-1. 도장재료비
B2: ■ qq5 적용 도장재료비
B3: *내장PAINT 재료비 (참조용) → SVR, 도막두께, 도료단가, 희석비율 구매팀 최종 확인 후 적용 할 것
B4: P/NAME | C4: GANH ASY RASPAD D/SIDE
B5: 칼라코드 | C5: QC1
B6: 도장구분 | C6: 고휘도 메탈도장 | H6: 도착효율 | I6: 0.23484428
B7: 도장특성 | C7: C | G7: 엠보무 | H7: 불량율 | I7: =3% -> 0.03
B8: 공정명 | C8: 재료명 | D8: 제품명 | E8: 단위 | F8: 단가 (\) | G8: SVR | H8: 도막두께 (㎛) | I8: 이론도포율 (㎡/ℓ) | J8: 재료비 (\/d㎡)
B9: 전처리 | C9: IPA | E9: ℓ | F9: 4912 | J9: =ROUNDDOWN(F9*540/10535563,2) -> 0.25
C10: TACK RAG (끈적천) | D10: 무광 미적용 | E10: 枚 | F10: 620 | J10: 0.20583998
C11: 소 계 | J11: =SUM(J9:J10) -> 0.45583998
B12: 도장 | C12: PRIMER | D12: SPZ#4900(TX-F) | E12: ℓ | F12: 31006 | G12: =(33.2+40.8)/2 -> 37 | H12: 18 | I12: =IF(F12=0,0,(G12*10)/H12) -> 20.555556 | J12: =IF(F12=0,0,ROUNDDOWN(F12/(I12*I6)/100,2)) -> 64.22
C13: 희석제 | D13: A/T#570(TX-F) | E13: ℓ | F13: 3780 | H13: 희석비율 = | I13: 1.2827234 | J13: =IF(F13=0,0,ROUNDDOWN(F13/(I12*I6)/100*I13,2)) -> 10.04
C14: BASE | D14: RESOTHANE-HT#800 | E14: ℓ | F14: 68314 | G14: =(17.2+25.7)/2 -> 21.45 | H14: 31 | I14: =IF(F14=0,0,(G14*10)/H14) -> 6.9193548 | J14: =ROUNDDOWN(F14/(I14*I6)/100,2) -> 420.4
C15: 희석제 | D15: A/T#800(TX-F) | E15: ℓ | F15: 5514 | H15: 희석비율 = | I15: 1.2855252 | J15: =ROUNDDOWN(F15/(I14*I6)/100*I15,2) -> 43.62
C16: CLEAR | E16: ℓ | F16: 0 | I16: =IF(F16=0,0,G16/H16*10) -> 0 | J16: =IF(F16=0,0,ROUNDDOWN(F16/(I16*I6)/100,2)) -> 0
C17: 희석제 | E17: ℓ | F17: 0 | H17: 희석비율 = | J17: =IF(F17=0,0,ROUNDDOWN(F17/(I16*I6)/100*I17,2)) -> 0
C18: 소 계 | J18: =SUM(J12:J17) -> 538.28
B19: 폐수처리비 (PL BPR도장 동일) | E19: d㎡ | J19: 2.2126575
B20: 건조연료비 (PL BPR도장 동일) | E20: d㎡ | J20: 6.8918987
I21: 도장재료비 (\/d㎡) | J21: =ROUNDDOWN((J11+J18+J19+J20)*(1+I7),2) -> 564.27
I23: PRIMER | J23: =(J12+J13)*(1+I7) -> 76.4878
I24: BASE | J24: =J21-J23 -> 487.7822

Sheet 1-2. 도장가공비
A1: ▣도장가공비 산출식
A3: ▣ 임율기준 : | C3: 36258 | E3: ▣ CVT기준 : | G3: 3 | I3: 노무비 | J3: 경비 | K3: 가공비 | L3: 일반 관리비 | M3: 이윤 | N3: 공정 총원가
I4: =ROUNDDOWN(I10/$G$3,2) -> 1352.49 | J4: =ROUNDDOWN(J10/$G$3,2) -> 122.55 | K4: =SUM(I4:J4) -> 1475.04 | L4: =ROUNDDOWN(K4*0.25,2) -> 368.76 | M4: =ROUNDDOWN((K4+L4)*0.15,2) -> 276.57 | N4: =SUM(K4:M4) -> 2120.37
A6: ▣ 1TONE PITCH 당 가공비(BASE)
A7: 구분 | C7: 라인스피드 | D7: PITCH | E7: C/TIME | F7: 인원 | G7: 임율 | H7: 경비 | I7: 노무비 | J7: 경비 | K7: 가공비 | L7: 일반관리비 /이윤 | M7: 불량률 | N7: 계 | O7: 합계 (/1+2%) | Q7: 전력단가 | R7: 249
A8: A TYPE | C8: 3.4698199 | D8: 1.9616823 | E8: 69 | F8: 16 | G8: =$C$3 -> 36258 | H8: =H25 -> 59141 | I8: =((E8*1.1/1*((F8*G8/3600)))) -> 12231.032 | J8: =(E8*1.1/1)*(H8*1.6)/3600 -> 1995.0231 | K8: =J8+I8 -> 14226.055 | L8: =K8*1.25*1.15-K8 -> 6223.8991 | M8: 0.011801323 | N8: =K8*(1+M8)+L8 -> 20617.84 | O8: =N8/1.02 -> 20213.569 | Q8: 건축비 | R8: 1008102
A9: B TYPE | C9: 1.3687519 | D9: 0.35573171 | E9: 18.182618 | F9: 17 | G9: =G8 -> 36258 | H9: =H26 -> 18372 | I9: =((E9*1.1/1*((F9*G9/3600)))) -> 3424.5172 | J9: =(E9*1.1/1)*(H9*1.6)/3600 -> 163.31385 | K9: =J9+I9 -> 3587.8311 | L9: =K9*1.25*1.15-K9 -> 1569.6761 | M9: 0.029477644 | N9: =K9*(1+M9)+L9 -> 5263.268 | O9: =N9/1.02 -> 5160.0667 | Q9: 용적률 | R9: 4.0661232
A10: C TYPE | C10: 1.24196 | D10: 0.6402092 | E10: 30.519744 | F10: 12 | G10: =G9 -> 36258 | H10: =H27 -> 24641 | I10: =((E10*1.1/1*((F10*G10/3600)))) -> 4057.4779 | J10: =(E10*1.1/1)*(H10*1.6)/3600 -> 367.66254 | K10: =J10+I10 -> 4425.1405 | L10: =K10*1.25*1.15-K10 -> 1935.999 | M10: 0.028416673 | N10: =K10*(1+M10)+L10 -> 6486.8872 | O10: =N10/1.02 -> 6359.6933 | Q10: 건물년수 | R10: 41
A11: D TYPE | C11: 4 | D11: 1.6113849 | E11: 68 | F11: 21 | G11: =G10 -> 36258 | H11: =H28 -> 32419 | I11: =((E11*1.1/1*((F11*G11/3600)))) -> 15820.574 | J11: =(E11*1.1/1)*(H11*1.6)/3600 -> 1077.7516 | K11: =J11+I11 -> 16898.326 | L11: =K11*1.25*1.15-K11 -> 7393.0175 | M11: 0.010422694 | N11: =K11*(1+M11)+L11 -> 24467.469 | O11: =N11/1.02 -> 23987.715 | Q11: 설비년수 | R11: 15
A12: E TYPE | C12: 2 | D12: 2 | E12: 162 | F12: 14 | G12: =G11 -> 36258 | H12: =H29 -> 41869 | I12: =((E12*1.1/1*((F12*G12/3600)))) -> 25126.794 | J12: =(E12*1.1/1)*(H12*1.6)/3600 -> 3316.0248 | K12: =J12+I12 -> 28442.819 | L12: =K12*1.25*1.15-K12 -> 12443.733 | M12: 0.040669975 | N12: =K12*(1+M12)+L12 -> 42043.321 | O12: =N12/1.02 -> 41218.942 | Q12: 간접비율 | R12: 0.57969033
A13: F TYPE | C13: 0.41467421 | D13: 0.49027535 | E13: 143 | F13: 17 | G13: =G12 -> 36258 | H13: =H30 -> 26961 | I13: =((E13*1.1/1*((F13*G13/3600)))) -> 26932.644 | J13: =(E13*1.1/1)*(H13*1.6)/3600 -> 1884.8735 | K13: =J13+I13 -> 28817.517 | L13: =K13*1.25*1.15-K13 -> 12607.664 | M13: 0.02888321 | N13: =K13*(1+M13)+L13 -> 42257.524 | O13: =N13/1.02 -> 41428.945 | Q13: 수선비율 | R13: 0.14136347
Q14: 년가동일 | R14: 772
A15: ▣ 1TONE PITCH 당 가공비(PRIMER+BASE) | Q15: 일가동시간 | R15: 43
A16: 구분 | C16: 라인스피드 | D16: PITCH | E16: C/TIME | F16: 인원 | G16: 임율 | H16: 경비 | I16: 노무비 | J16: 경비 | K16: 가공비 | L16: 일반관리비 /이윤 | M16: 불량률 | N16: 계 | O16: 합계 (/1+2%)
A17: A TYPE | C17: 3.6460652 | D17: 1.8828515 | E17: 35 | F17: 13 | G17: =$C$3 -> 36258 | H17: =H25 -> 59141 | I17: =((E17*1.1/1*((F17*G17/3600)))) -> 5040.8692 | J17: =(E17*1.1/1)*(H17*1.6)/3600 -> 1011.9682 | K17: =J17+I17 -> 6052.8374 | L17: =K17*1.25*1.15-K17 -> 2648.1164 | M17: 0.0091342387 | N17: =K17*(1+M17)+L17 -> 8756.2418 | O17: =N17/1.02 -> 8584.5508
A18: B TYPE | C18: 1.098232 | D18: 0.34441597 | E18: 17.037584 | F18: 16 | G18: =G17 -> 36258 | H18: =H26 -> 18372 | I18: =((E18*1.1/1*((F18*G18/3600)))) -> 3020.1049 | J18: =(E18*1.1/1)*(H18*1.6)/3600 -> 153.02931 | K18: =J18+I18 -> 3173.1342 | L18: =K18*1.25*1.15-K18 -> 1388.2462 | M18: 0.030701338 | N18: =K18*(1+M18)+L18 -> 4658.7998 | O18: =N18/1.02 -> 4567.4508
A19: C TYPE | C19: 1.5128676 | D19: 0.49030745 | E19: 25.404666 | F19: 10 | G19: =G18 -> 36258 | H19: =H27 -> 24641 | I19: =((E19*1.1/1*((F19*G19/3600)))) -> 2814.5406 | J19: =(E19*1.1/1)*(H19*1.6)/3600 -> 306.04268 | K19: =J19+I19 -> 3120.5833 | L19: =K19*1.25*1.15-K19 -> 1365.2552 | M19: 0.027742046 | N19: =K19*(1+M19)+L19 -> 4572.4099 | O19: =N19/1.02 -> 4482.7548
A20: D TYPE | C20: 6 | D20: 1.3595543 | E20: 59 | F20: 18 | G20: =G19 -> 36258 | H20: =H28 -> 32419 | I20: =((E20*1.1/1*((F20*G20/3600)))) -> 11765.721 | J20: =(E20*1.1/1)*(H20*1.6)/3600 -> 935.10804 | K20: =J20+I20 -> 12700.829 | L20: =K20*1.25*1.15-K20 -> 5556.6127 | M20: 0.011637193 | N20: =K20*(1+M20)+L20 -> 18405.244 | O20: =N20/1.02 -> 18044.357
A21: E TYPE | C21: 2 | D21: 2 | E21: 111 | F21: 32 | G21: =G20 -> 36258 | H21: =H29 -> 41869 | I21: =((E21*1.1/1*((F21*G21/3600)))) -> 39352.016 | J21: =(E21*1.1/1)*(H21*1.6)/3600 -> 2272.0911 | K21: =J21+I21 -> 41624.107 | L21: =K21*1.25*1.15-K21 -> 18210.547 | M21: 0.034607073 | N21: =K21*(1+M21)+L21 -> 61275.142 | O21: =N21/1.02 -> 60073.669
A22: F TYPE | C22: 0.41192337 | D22: 0.44866214 | E22: 151 | F22: 29 | G22: =G21 -> 36258 | H22: =H30 -> 26961 | I22: =((E22*1.1/1*((F22*G22/3600)))) -> 48514.211 | J22: =(E22*1.1/1)*(H22*1.6)/3600 -> 1990.3209 | K22: =J22+I22 -> 50504.532 | L22: =K22*1.25*1.15-K22 -> 22095.733 | M22: 0.028144021 | N22: =K22*(1+M22)+L22 -> 74021.666 | O22: =N22/1.02 -> 72570.26
A24: 제품특성 | C24: 소비율 | D24: 전력용량 | E24: 설치면적 | F24: 기계가액 | H24: 직접경비 | J24: 전력비 | K24: 건물상각비 | L24: 기계상각비 | M24: 수선비
A25: A TYPE | C25: 0.49390233 | D25: 392 | E25: 453.41463 | F25: 4089588 | H25: =ROUNDDOWN((D25*C25*$R$7+E25*$R$9*$R$8/$R$14/$R$10/$R$15+F25*1000/$R$11/$R$14/$R$15+(E25*$R$9*$R$8/$R$14/$R$10/$R$15+F25*1000/$R$11/$R$14/$R$15)*$R$13),0) -> 59141 | J25: =D25*46/100*$R$7 -> 44899.68 | K25: =E25*$R$9*$R$8/$R$10/$R$14/$R$15 -> 1365.5604 | L25: =F25*1000/($R$11*$R$14*$R$15) -> 8213.0136 | M25: =(K25+L25)*$R$13 -> 1354.0604
A26: B TYPE | C26: 0.45696185 | D26: 138.92115 | E26: 94.092083 | F26: 978325 | H26: =ROUNDDOWN((D26*C26*$R$7+E26*$R$9*$R$8/$R$14/$R$10/$R$15+F26*1000/$R$11/$R$14/$R$15+(E26*$R$9*$R$8/$R$14/$R$10/$R$15+F26*1000/$R$11/$R$14/$R$15)*$R$13),0) -> 18372 | J26: =D26*46/100*$R$7 -> 15912.028 | K26: =E26*$R$9*$R$8/$R$10/$R$14/$R$15 -> 283.37953 | L26: =F26*1000/($R$11*$R$14*$R$15) -> 1964.7447 | M26: =(K26+L26)*$R$13 -> 317.80264
A27: C TYPE | C27: 0.54193162 | D27: 167.05789 | E27: 72.555278 | F27: 806840 | H27: =ROUNDDOWN((D27*C27*$R$7+E27*$R$9*$R$8/$R$14/$R$10/$R$15+F27*1000/$R$11/$R$14/$R$15+(E27*$R$9*$R$8/$R$14/$R$10/$R$15+F27*1000/$R$11/$R$14/$R$15)*$R$13),0) -> 24641 | J27: =D27*46/100*$R$7 -> 19134.811 | K27: =E27*$R$9*$R$8/$R$10/$R$14/$R$15 -> 218.51659 | L27: =F27*1000/($R$11*$R$14*$R$15) -> 1620.3559 | M27: =(K27+L27)*$R$13 -> 259.94939
A28: D TYPE | C28: 0.54550646 | D28: 215 | E28: 436 | F28: 749135 | H28: =ROUNDDOWN((D28*C28*$R$7+E28*$R$9*$R$8/$R$14/$R$10/$R$15+F28*1000/$R$11/$R$14/$R$15+(E28*$R$9*$R$8/$R$14/$R$10/$R$15+F28*1000/$R$11/$R$14/$R$15)*$R$13),0) -> 32419 | J28: =D28*46/100*$R$7 -> 24626.1 | K28: =E28*$R$9*$R$8/$R$10/$R$14/$R$15 -> 1313.1123 | L28: =F28*1000/($R$11*$R$14*$R$15) -> 1504.4684 | M28: =(K28+L28)*$R$13 -> 398.30298
A29: E TYPE | C29: 0.42196714 | D29: 329 | E29: 1307 | F29: 1225423 | H29: =ROUNDDOWN((D29*C29*$R$7+E29*$R$9*$R$8/$R$14/$R$10/$R$15+F29*1000/$R$11/$R$14/$R$15+(E29*$R$9*$R$8/$R$14/$R$10/$R$15+F29*1000/$R$11/$R$14/$R$15)*$R$13),0) -> 41869 | J29: =D29*46/100*$R$7 -> 37683.66 | K29: =E29*$R$9*$R$8/$R$10/$R$14/$R$15 -> 3936.3253 | L29: =F29*1000/($R$11*$R$14*$R$15) -> 2460.9853 | M29: =(K29+L29)*$R$13 -> 904.346
A30: F TYPE | C30: 0.37805535 | D30: 276 | E30: 33.796263 | F30: 376756 | H30: =ROUNDDOWN((D30*C30*$R$7+E30*$R$9*$R$8/$R$14/$R$10/$R$15+F30*1000/$R$11/$R$14/$R$15+(E30*$R$9*$R$8/$R$14/$R$10/$R$15+F30*1000/$R$11/$R$14/$R$15)*$R$13),0) -> 26961 | J30: =D30*46/100*$R$7 -> 31613.04 | K30: =E30*$R$9*$R$8/$R$10/$R$14/$R$15 -> 101.78507 | L30: =F30*1000/($R$11*$R$14*$R$15) -> 756.62931 | M30: =(K30+L30)*$R$13 -> 121.34843

Sheet 1-3. 도면

Sheet 1-4 PAD
A1: 일반 PAD 부품계산서
A4: 기 | B4: 차종 | C4: 년생산댓수 | D4: 총수량 | E4: 작성자 | F4: 김민석 | G4: 계산근거 | H4: HMK-P-G-TR-03 일반PAD 원가계산 표준 | K4: 임율기준 | L4: 임률 | M4: 간접비율 | N4: 일반관리비율 | O4: 전력단가 | P4: 건축비 | Q4: 부대설비비율 | R4: 기계내용년수 | S4: 건물상각년수 | T4: 년간가동일수 | U4: 일일가동시간 | V4: 수선비율 | W4: 경영비율 | Y4: ↓ 입력
A5: 준 | B5: qq5 | C5: 396548 | D5: =+C5*5 -> 1982740 | E5: 작성일 | F5: 2019.08.09 | G5: 개 정 일 | H5: 2018.12.10(18차개정) | K5: '21년도 | L5: {=INDEX($AK$80:$AL$89,MATCH($K$5,$AK$80:$AK$89,0),2)} -> 21600 | M5: 0.71071277 | N5: 0.26470793 | O5: =118 -> 118 | P5: 723710 | Q5: 2.903751 | R5: 18 | S5: 85 | T5: 656 | U5: 43 | V5: 0.12729054 | W5: 0.88722982
A7: 1]부품Spec | L7: ※재질단가는 최신기준 확인후 수정사용 | Z7: 재료비
A8: S/N | B8: 부번 | C8: 품명 | D8: U/S | E8: 제품Size(mm) | I8: 적용공정 | J8: 년간수량 (부품) | K8: 제품Net | L8: 스폰지 | P8: 테이핑 | T8: 기타 | V8: 설계원가 | W8: 공정 (두께기준 산출) | X8: Loss율 | Z8: Cavity | AB8: Sheet규격(mm) | AD8: LOT수량 | AE8: 면적(㎠) | AH8: Cavity | AK8: Sheet규격 | AM8: 여유규격 | AO8: Cavity1 | AR8: Cavity2 | AU8: 결정 Cavity
E9: 가로(장변) | F9: 세로(단변) | G9: 두께(T) | H9: 형태 | K9: 면적(㎠) | L9: 사양 | M9: 세부재질(선택) | N9: 스폰지단가 | O9: 비중 | P9: 테이프사양 | Q9: 테이핑구분 | R9: 후테이핑횟수 | S9: 테이프단가 | T9: 트리밍횟수 | U9: V/CUT길이(㎝) | X9: Pad | Y9: Tape | Z9: 가로 | AA9: 세로 | AB9: 가로 | AC9: 세로 | AD9: 기준 | AE9: 제품면적 | AF9: 투입면적 | AG9: Scrap면적 | AH9: 형상컷팅 | AI9: 테이핑 | AJ9: 재단 | AK9: 가로 ⓐ | AL9: 세로 ⓑ | AM9: Sheet ⓒ | AN9: 제품간 ⓓ | AO9: 가로 | AP9: 세로 | AR9: 가로 | AS9: 세로
A10: 1 | B10: 84520-98020 | C10: PAD ANTINOSE NO.3 | D10: 12 | E10: 24 | F10: 23 | G10: 0.54616672 | H10: 직형 | I10: =IF(AND($W10="오토컷팅",E10<=290),"오토컷팅",IF(AND(OR(W10="오토컷팅",$W10="파워프레스"),E10<=600),"파워프레스","롤컷팅")) -> 오토컷팅 | J10: =$C$5*D10 -> 4758576 | K10: =E10*F10/100 -> 5.52 | L10: =IF($M10="","",INDEX($Z$109:$AC$162,MATCH($M10,$Z$109:$Z$162,0),4)) -> 일반 FOAM | M10: 흑색부직포(100g/㎡) | N10: =IF($M10="",0,INDEX($Z$109:$AC$162,MATCH($M10,$Z$109:$Z$162,0),3)) -> 682 | O10: =IF($M10="",0,INDEX($Z$109:$AB$162,MATCH($M10,$Z$109:$Z$162,0),2)) -> 0.1 | P10: P-300 | Q10: =IF($E10=0,"",IF(OR($P10="",$P10="무점착",$P10="단면TAPE P-100",$P10="H-100"),"미적용",IF(OR($I10="오토컷팅",$I10="파워프레스"),"ROLL","SHEET"))) -> ROLL | S10: =IF($P10="",0,INDEX($Z$167:$AA$212,MATCH($P10,$Z$167:$Z$212,0),2)) -> 2693 | V10: =IF($E10=0,0,ROUND(SUM($P45:$S45),1)) -> 23.7 | W10: =IF($E10=0,"",IF(AND($E10>=601,$H10="직형"),"롤컷팅",INDEX($Y$95:$AD$101,MATCH($L10,$Y$95:$Y$101,0),MATCH($G10,$Y$94:$AD$94,-1)))) -> 오토컷팅 | X10: =IF($E10=0,0,1%) -> 0.01 | Y10: =IF($E10=0,0,IF(OR($P10="단면TAPE P-100",$P10="양면TAPE P-200",$P10="SEAT BACK/CUSION 용",$P10="P-300",$P10="P-400",$P10="H-100"),$X10,5%)) -> 0.01 | Z10: =IF($AQ10>$AT10,$AO10,$AS10) -> 1 | AA10: =IF($AQ10>$AT10,$AP10,$AR10) -> 11 | AB10: =(E10*Z10)+(AM10*2)+(AN10*(Z10-1)) -> 44 | AC10: =(F10*AA10)+(AM10*2)+(AN10*(AA10-1)) -> 273 | AD10: =IF($E10=0,0,INDEX($AI$80:$AJ$109,MATCH($J10,$AI$80:$AI$109,-1),2)) -> 12000 | AE10: =IF($E10=0,0,($AB10/$Z10*$AC10/$AA10)/100) -> 10.92 | AF10: =$AE10 -> 10.92 | AG10: =$AE10-$K10 -> 5.4 | AH10: =IF($I10=$AM$81,$Z10*$AA10,IF($I10=$AM$82,$Z10*$AA10*INT(50/G10),IF(AND($I10=$AM$84,$G10<=50),$Z10*$AA10*INT(50/$G10),IF(AND($I10=$AM$84,$G10>50),$Z10*$AA10,0)))) -> 11 | AI10: =IF($E10=0,0,INT($AP$85/($AE10))) -> 641 | AJ10: =IF($I10="오토컷팅",INT($AP$86/$AF10),IF($I10="파워프레스",INT($AP$87/$AF10),IF($I10="롤컷팅",INT($AP$88/$AF10),0))) -> 457 | AK10: =VLOOKUP($I10,$AM$81:$AO$84,2,0) -> 150 | AL10: =VLOOKUP($I10,$AM$81:$AO$84,3,0) -> 290 | AM10: =IF(AND($I10="오토컷팅",$E10>=280),0,IF(AND($I10="파워프레스",$E10>=590),0,10)) -> 10 | AN10: =IF($H10="직형",0,5) -> 0 | AO10: 1 | AP10: =INT(($AL10-$AM10*2+$AN10)/($F10+$AN10)) -> 11 | AQ10: =$AO10*$AP10 -> 11 | AR10: =INT(($AK10-$AM10*2+$AN10)/($F10+$AN10)) -> 5 | AS10: 1 | AT10: =$AR10*$AS10 -> 5 | AU10: =MAX($AQ10,$AT10) -> 11
A11: 2 | B11: 55596-P1020 | C11: PAD ANTINOSE NO.5 | D11: 2 | E11: 51 | F11: 22 | G11: 0.59008269 | H11: 직형 | I11: =IF(AND($W11="오토컷팅",E11<=290),"오토컷팅",IF(AND(OR(W11="오토컷팅",$W11="파워프레스"),E11<=600),"파워프레스","롤컷팅")) -> 오토컷팅 | J11: =$C$5*D11 -> 793096 | K11: =E11*F11/100 -> 11.22 | L11: =IF($M11="","",INDEX($Z$109:$AC$162,MATCH($M11,$Z$109:$Z$162,0),4)) -> 일반 FOAM | M11: 흑색부직포(100g/㎡) | N11: =IF($M11="",0,INDEX($Z$109:$AC$162,MATCH($M11,$Z$109:$Z$162,0),3)) -> 682 | O11: =IF($M11="",0,INDEX($Z$109:$AB$162,MATCH($M11,$Z$109:$Z$162,0),2)) -> 0.1 | P11: P-300 | Q11: =IF($E11=0,"",IF(OR($P11="",$P11="무점착",$P11="단면TAPE P-100",$P11="H-100"),"미적용",IF(OR($I11="오토컷팅",$I11="파워프레스"),"ROLL","SHEET"))) -> ROLL | S11: =IF($P11="",0,INDEX($Z$167:$AA$212,MATCH($P11,$Z$167:$Z$212,0),2)) -> 2693 | V11: =IF($E11=0,0,ROUND(SUM($P46:$S46),1)) -> 24.4 | W11: =IF($E11=0,"",IF(AND($E11>=601,$H11="직형"),"롤컷팅",INDEX($Y$95:$AD$101,MATCH($L11,$Y$95:$Y$101,0),MATCH($G11,$Y$94:$AD$94,-1)))) -> 오토컷팅 | X11: =IF($E11=0,0,1%) -> 0.01 | Y11: =IF($E11=0,0,IF(OR($P11="단면TAPE P-100",$P11="양면TAPE P-200",$P11="SEAT BACK/CUSION 용",$P11="P-300",$P11="P-400",$P11="H-100"),$X11,5%)) -> 0.01 | Z11: =IF($AQ11>$AT11,$AO11,$AS11) -> 5 | AA11: =IF($AQ11>$AT11,$AP11,$AR11) -> 5 | AB11: =(E11*Z11)+(AM11*2)+(AN11*(Z11-1)) -> 275 | AC11: =(F11*AA11)+(AM11*2)+(AN11*(AA11-1)) -> 130 | AD11: =IF($E11=0,0,INDEX($AI$80:$AJ$109,MATCH($J11,$AI$80:$AI$109,-1),2)) -> 8000 | AE11: =IF($E11=0,0,($AB11/$Z11*$AC11/$AA11)/100) -> 14.3 | AF11: =$AE11 -> 14.3 | AG11: =$AE11-$K11 -> 3.08 | AH11: =IF($I11=$AM$81,$Z11*$AA11,IF($I11=$AM$82,$Z11*$AA11*INT(50/G11),IF(AND($I11=$AM$84,$G11<=50),$Z11*$AA11*INT(50/$G11),IF(AND($I11=$AM$84,$G11>50),$Z11*$AA11,0)))) -> 25 | AI11: =IF($E11=0,0,INT($AP$85/($AE11))) -> 489 | AJ11: =IF($I11="오토컷팅",INT($AP$86/$AF11),IF($I11="파워프레스",INT($AP$87/$AF11),IF($I11="롤컷팅",INT($AP$88/$AF11),0))) -> 349 | AK11: =VLOOKUP($I11,$AM$81:$AO$84,2,0) -> 150 | AL11: =VLOOKUP($I11,$AM$81:$AO$84,3,0) -> 290 | AM11: =IF(AND($I11="오토컷팅",$E11>=280),0,IF(AND($I11="파워프레스",$E11>=590),0,10)) -> 10 | AN11: =IF($H11="직형",0,5) -> 0 | AO11: =INT(($AK11-$AM11*2+$AN11)/($E11+$AN11)) -> 2 | AP11: =INT(($AL11-$AM11*2+$AN11)/($F11+$AN11)) -> 12 | AQ11: =$AO11*$AP11 -> 24 | AR11: =INT(($AK11-$AM11*2+$AN11)/($F11+$AN11)) -> 5 | AS11: =INT(($AL11-$AM11*2+$AN11)/($E11+$AN11)) -> 5 | AT11: =$AR11*$AS11 -> 25 | AU11: =MAX($AQ11,$AT11) -> 25
A12: 7 | B12: 55591-P1010 | C12: PAD ANTINOSE NO.7 | D12: 2 | E12: 34 | F12: 22 | G12: 0.5850901 | H12: 직형 | I12: =IF(AND($W12="오토컷팅",E12<=290),"오토컷팅",IF(AND(OR(W12="오토컷팅",$W12="파워프레스"),E12<=600),"파워프레스","롤컷팅")) -> 오토컷팅 | J12: =$C$5*D12 -> 793096 | K12: =E12*F12/100 -> 7.48 | L12: =IF($M12="","",INDEX($Z$109:$AC$162,MATCH($M12,$Z$109:$Z$162,0),4)) -> 일반 FOAM | M12: 흑색부직포(100g/㎡) | N12: =IF($M12="",0,INDEX($Z$109:$AC$162,MATCH($M12,$Z$109:$Z$162,0),3)) -> 682 | O12: =IF($M12="",0,INDEX($Z$109:$AB$162,MATCH($M12,$Z$109:$Z$162,0),2)) -> 0.1 | P12: P-300 | Q12: =IF($E12=0,"",IF(OR($P12="",$P12="무점착",$P12="단면TAPE P-100",$P12="H-100"),"미적용",IF(OR($I12="오토컷팅",$I12="파워프레스"),"ROLL","SHEET"))) -> ROLL | S12: =IF($P12="",0,INDEX($Z$167:$AA$212,MATCH($P12,$Z$167:$Z$212,0),2)) -> 2693 | V12: =IF($E12=0,0,ROUND(SUM($P47:$S47),1)) -> 17.5 | W12: =IF($E12=0,"",IF(AND($E12>=601,$H12="직형"),"롤컷팅",INDEX($Y$95:$AD$101,MATCH($L12,$Y$95:$Y$101,0),MATCH($G12,$Y$94:$AD$94,-1)))) -> 오토컷팅 | X12: =IF($E12=0,0,1%) -> 0.01 | Y12: =IF($E12=0,0,IF(OR($P12="단면TAPE P-100",$P12="양면TAPE P-200",$P12="SEAT BACK/CUSION 용",$P12="P-300",$P12="P-400",$P12="H-100"),$X12,5%)) -> 0.01 | Z12: =IF($AQ12>$AT12,$AO12,$AS12) -> 3 | AA12: =IF($AQ12>$AT12,$AP12,$AR12) -> 12 | AB12: =(E12*Z12)+(AM12*2)+(AN12*(Z12-1)) -> 122 | AC12: =(F12*AA12)+(AM12*2)+(AN12*(AA12-1)) -> 284 | AD12: =IF($E12=0,0,INDEX($AI$80:$AJ$109,MATCH($J12,$AI$80:$AI$109,-1),2)) -> 8000 | AE12: =IF($E12=0,0,($AB12/$Z12*$AC12/$AA12)/100) -> 9.6244444 | AF12: =$AE12 -> 9.6244444 | AG12: =$AE12-$K12 -> 2.1444444 | AH12: =IF($I12=$AM$81,$Z12*$AA12,IF($I12=$AM$82,$Z12*$AA12*INT(50/G12),IF(AND($I12=$AM$84,$G12<=50),$Z12*$AA12*INT(50/$G12),IF(AND($I12=$AM$84,$G12>50),$Z12*$AA12,0)))) -> 36 | AI12: =IF($E12=0,0,INT($AP$85/($AE12))) -> 727 | AJ12: =IF($I12="오토컷팅",INT($AP$86/$AF12),IF($I12="파워프레스",INT($AP$87/$AF12),IF($I12="롤컷팅",INT($AP$88/$AF12),0))) -> 519 | AK12: =VLOOKUP($I12,$AM$81:$AO$84,2,0) -> 150 | AL12: =VLOOKUP($I12,$AM$81:$AO$84,3,0) -> 290 | AM12: =IF(AND($I12="오토컷팅",$E12>=280),0,IF(AND($I12="파워프레스",$E12>=590),0,10)) -> 10 | AN12: =IF($H12="직형",0,5) -> 0 | AO12: =INT(($AK12-$AM12*2+$AN12)/($E12+$AN12)) -> 3 | AP12: =INT(($AL12-$AM12*2+$AN12)/($F12+$AN12)) -> 12 | AQ12: =$AO12*$AP12 -> 36 | AR12: =INT(($AK12-$AM12*2+$AN12)/($F12+$AN12)) -> 5 | AS12: =INT(($AL12-$AM12*2+$AN12)/($E12+$AN12)) -> 7 | AT12: =$AR12*$AS12 -> 35 | AU12: =MAX($AQ12,$AT12) -> 36
A13: 4 | I13: =IF(AND($W13="오토컷팅",E13<=290),"오토컷팅",IF(AND(OR(W13="오토컷팅",$W13="파워프레스"),E13<=600),"파워프레스","롤컷팅")) -> 롤컷팅 | J13: =$C$5*D13 -> 0 | K13: =E13*F13/100 -> 0 | L13: =IF($M13="","",INDEX($Z$109:$AC$162,MATCH($M13,$Z$109:$Z$162,0),4)) | N13: =IF($M13="",0,INDEX($Z$109:$AC$162,MATCH($M13,$Z$109:$Z$162,0),3)) -> 0 | O13: =IF($M13="",0,INDEX($Z$109:$AB$162,MATCH($M13,$Z$109:$Z$162,0),2)) -> 0 | Q13: =IF($E13=0,"",IF(OR($P13="",$P13="무점착",$P13="단면TAPE P-100",$P13="H-100"),"미적용",IF(OR($I13="오토컷팅",$I13="파워프레스"),"ROLL","SHEET"))) | S13: =IF($P13="",0,INDEX($Z$167:$AA$212,MATCH($P13,$Z$167:$Z$212,0),2)) -> 0 | V13: =IF($E13=0,0,ROUND(SUM($P48:$S48),1)) -> 0 | W13: =IF($E13=0,"",IF(AND($E13>=601,$H13="직형"),"롤컷팅",INDEX($Y$95:$AD$101,MATCH($L13,$Y$95:$Y$101,0),MATCH($G13,$Y$94:$AD$94,-1)))) | X13: =IF($E13=0,0,1%) -> 0 | Y13: =IF($E13=0,0,IF(OR($P13="단면TAPE P-100",$P13="양면TAPE P-200",$P13="SEAT BACK/CUSION 용",$P13="P-300",$P13="P-400",$P13="H-100"),$X13,5%)) -> 0 | Z13: =IF($AQ13>$AT13,$AO13,$AS13) -> 137 | AA13: =IF($AQ13>$AT13,$AP13,$AR13) -> 117 | AB13: =(E13*Z13)+(AM13*2)+(AN13*(Z13-1)) -> 700 | AC13: =(F13*AA13)+(AM13*2)+(AN13*(AA13-1)) -> 600 | AD13: =IF($E13=0,0,INDEX($AI$80:$AJ$109,MATCH($J13,$AI$80:$AI$109,-1),2)) -> 0 | AE13: =IF($E13=0,0,($AB13/$Z13*$AC13/$AA13)/100) -> 0 | AF13: =$AE13 -> 0 | AG13: =$AE13-$K13 -> 0 | AH13: =IF($I13=$AM$81,$Z13*$AA13,IF($I13=$AM$82,$Z13*$AA13*INT(50/G13),IF(AND($I13=$AM$84,$G13<=50),$Z13*$AA13*INT(50/$G13),IF(AND($I13=$AM$84,$G13>50),$Z13*$AA13,0)))) -> #DIV/0! | AI13: =IF($E13=0,0,INT($AP$85/($AE13))) -> 0 | AJ13: =IF($I13="오토컷팅",INT($AP$86/$AF13),IF($I13="파워프레스",INT($AP$87/$AF13),IF($I13="롤컷팅",INT($AP$88/$AF13),0))) -> #DIV/0! | AK13: =VLOOKUP($I13,$AM$81:$AO$84,2,0) -> 600 | AL13: =VLOOKUP($I13,$AM$81:$AO$84,3,0) -> 700 | AM13: =IF(AND($I13="오토컷팅",$E13>=280),0,IF(AND($I13="파워프레스",$E13>=590),0,10)) -> 10 | AN13: =IF($H13="직형",0,5) -> 5 | AO13: =INT(($AK13-$AM13*2+$AN13)/($E13+$AN13)) -> 117 | AP13: =INT(($AL13-$AM13*2+$AN13)/($F13+$AN13)) -> 137 | AQ13: =$AO13*$AP13 -> 16029 | AR13: =INT(($AK13-$AM13*2+$AN13)/($F13+$AN13)) -> 117 | AS13: =INT(($AL13-$AM13*2+$AN13)/($E13+$AN13)) -> 137 | AT13: =$AR13*$AS13 -> 16029 | AU13: =MAX($AQ13,$AT13) -> 16029
A14: 7 | I14: =IF(AND($W14="오토컷팅",E14<=290),"오토컷팅",IF(AND(OR(W14="오토컷팅",$W14="파워프레스"),E14<=600),"파워프레스","롤컷팅")) -> 롤컷팅 | J14: =$C$5*D14 -> 0 | K14: =E14*F14/100 -> 0 | L14: =IF($M14="","",INDEX($Z$109:$AC$162,MATCH($M14,$Z$109:$Z$162,0),4)) | N14: =IF($M14="",0,INDEX($Z$109:$AC$162,MATCH($M14,$Z$109:$Z$162,0),3)) -> 0 | O14: =IF($M14="",0,INDEX($Z$109:$AB$162,MATCH($M14,$Z$109:$Z$162,0),2)) -> 0 | Q14: =IF($E14=0,"",IF(OR($P14="",$P14="무점착",$P14="단면TAPE P-100",$P14="H-100"),"미적용",IF(OR($I14="오토컷팅",$I14="파워프레스"),"ROLL","SHEET"))) | S14: =IF($P14="",0,INDEX($Z$167:$AA$212,MATCH($P14,$Z$167:$Z$212,0),2)) -> 0 | V14: =IF($E14=0,0,ROUND(SUM($P49:$S49),1)) -> 0 | W14: =IF($E14=0,"",IF(AND($E14>=601,$H14="직형"),"롤컷팅",INDEX($Y$95:$AD$101,MATCH($L14,$Y$95:$Y$101,0),MATCH($G14,$Y$94:$AD$94,-1)))) | X14: =IF($E14=0,0,1%) -> 0 | Y14: =IF($E14=0,0,IF(OR($P14="단면TAPE P-100",$P14="양면TAPE P-200",$P14="SEAT BACK/CUSION 용",$P14="P-300",$P14="P-400",$P14="H-100"),$X14,5%)) -> 0 | Z14: =IF($AQ14>$AT14,$AO14,$AS14) -> 137 | AA14: =IF($AQ14>$AT14,$AP14,$AR14) -> 117 | AB14: =(E14*Z14)+(AM14*2)+(AN14*(Z14-1)) -> 700 | AC14: =(F14*AA14)+(AM14*2)+(AN14*(AA14-1)) -> 600 | AD14: =IF($E14=0,0,INDEX($AI$80:$AJ$109,MATCH($J14,$AI$80:$AI$109,-1),2)) -> 0 | AE14: =IF($E14=0,0,($AB14/$Z14*$AC14/$AA14)/100) -> 0 | AF14: =$AE14 -> 0 | AG14: =$AE14-$K14 -> 0 | AH14: =IF($I14=$AM$81,$Z14*$AA14,IF($I14=$AM$82,$Z14*$AA14*INT(50/G14),IF(AND($I14=$AM$84,$G14<=50),$Z14*$AA14*INT(50/$G14),IF(AND($I14=$AM$84,$G14>50),$Z14*$AA14,0)))) -> #DIV/0! | AI14: =IF($E14=0,0,INT($AP$85/($AE14))) -> 0 | AJ14: =IF($I14="오토컷팅",INT($AP$86/$AF14),IF($I14="파워프레스",INT($AP$87/$AF14),IF($I14="롤컷팅",INT($AP$88/$AF14),0))) -> #DIV/0! | AK14: =VLOOKUP($I14,$AM$81:$AO$84,2,0) -> 600 | AL14: =VLOOKUP($I14,$AM$81:$AO$84,3,0) -> 700 | AM14: =IF(AND($I14="오토컷팅",$E14>=280),0,IF(AND($I14="파워프레스",$E14>=590),0,10)) -> 10 | AN14: =IF($H14="직형",0,5) -> 5 | AO14: =INT(($AK14-$AM14*2+$AN14)/($E14+$AN14)) -> 117 | AP14: =INT(($AL14-$AM14*2+$AN14)/($F14+$AN14)) -> 137 | AQ14: =$AO14*$AP14 -> 16029 | AR14: =INT(($AK14-$AM14*2+$AN14)/($F14+$AN14)) -> 117 | AS14: =INT(($AL14-$AM14*2+$AN14)/($E14+$AN14)) -> 137 | AT14: =$AR14*$AS14 -> 16029 | AU14: =MAX($AQ14,$AT14) -> 16029
